INFO:     Started server process [1353011]
INFO:     Waiting for application startup.
INFO:     Application startup complete.
INFO:     Uvicorn running on http://0.0.0.0:8000 (Press CTRL+C to quit)
INFO:     Started server process [1353236]
INFO:     Waiting for application startup.
INFO:     Application startup complete.
INFO:     Uvicorn running on http://0.0.0.0:8000 (Press CTRL+C to quit)
INFO:     127.0.0.1:43082 - "GET / HTTP/1.1" 200 OK
INFO:     Started server process [1353678]
INFO:     Waiting for application startup.
INFO:     Application startup complete.
INFO:     Uvicorn running on http://0.0.0.0:8000 (Press CTRL+C to quit)
INFO:     Started server process [1353889]
INFO:     Waiting for application startup.
INFO:     Application startup complete.
ERROR:    [Errno 13] error while attempting to bind on address ('0.0.0.0', 80): permission denied
INFO:     Waiting for application shutdown.
INFO:     Application shutdown complete.
nohup: ignoring input
nohup: failed to run command 'uvicorn': No such file or directory
nohup: failed to run command 'uvicorn': No such file or directory
nohup: failed to run command 'uvicorn': No such file or directory
Traceback (most recent call last):
  File "/home/ubuntu/.cache/pypoetry/virtualenvs/eggtart-QxCesdUQ-py3.12/bin/uvicorn", line 8, in <module>
    sys.exit(main())
             ^^^^^^
  File "/home/ubuntu/.cache/pypoetry/virtualenvs/eggtart-QxCesdUQ-py3.12/lib/python3.12/site-packages/click/core.py", line 1157, in __call__
    return self.main(*args, **kwargs)
           ^^^^^^^^^^^^^^^^^^^^^^^^^^
  File "/home/ubuntu/.cache/pypoetry/virtualenvs/eggtart-QxCesdUQ-py3.12/lib/python3.12/site-packages/click/core.py", line 1078, in main
    rv = self.invoke(ctx)
         ^^^^^^^^^^^^^^^^
  File "/home/ubuntu/.cache/pypoetry/virtualenvs/eggtart-QxCesdUQ-py3.12/lib/python3.12/site-packages/click/core.py", line 1434, in invoke
    return ctx.invoke(self.callback, **ctx.params)
           ^^^^^^^^^^^^^^^^^^^^^^^^^^^^^^^^^^^^^^^
  File "/home/ubuntu/.cache/pypoetry/virtualenvs/eggtart-QxCesdUQ-py3.12/lib/python3.12/site-packages/click/core.py", line 783, in invoke
    return __callback(*args, **kwargs)
           ^^^^^^^^^^^^^^^^^^^^^^^^^^^
  File "/home/ubuntu/.cache/pypoetry/virtualenvs/eggtart-QxCesdUQ-py3.12/lib/python3.12/site-packages/uvicorn/main.py", line 409, in main
    run(
  File "/home/ubuntu/.cache/pypoetry/virtualenvs/eggtart-QxCesdUQ-py3.12/lib/python3.12/site-packages/uvicorn/main.py", line 575, in run
    server.run()
  File "/home/ubuntu/.cache/pypoetry/virtualenvs/eggtart-QxCesdUQ-py3.12/lib/python3.12/site-packages/uvicorn/server.py", line 62, in run
    return asyncio.run(self.serve(sockets=sockets))
           ^^^^^^^^^^^^^^^^^^^^^^^^^^^^^^^^^^^^^^^^
  File "/usr/lib/python3.12/asyncio/runners.py", line 194, in run
    return runner.run(main)
           ^^^^^^^^^^^^^^^^
  File "/usr/lib/python3.12/asyncio/runners.py", line 118, in run
    return self._loop.run_until_complete(task)
           ^^^^^^^^^^^^^^^^^^^^^^^^^^^^^^^^^^^
  File "/usr/lib/python3.12/asyncio/base_events.py", line 687, in run_until_complete
    return future.result()
           ^^^^^^^^^^^^^^^
  File "/home/ubuntu/.cache/pypoetry/virtualenvs/eggtart-QxCesdUQ-py3.12/lib/python3.12/site-packages/uvicorn/server.py", line 69, in serve
    config.load()
  File "/home/ubuntu/.cache/pypoetry/virtualenvs/eggtart-QxCesdUQ-py3.12/lib/python3.12/site-packages/uvicorn/config.py", line 433, in load
    self.loaded_app = import_from_string(self.app)
                      ^^^^^^^^^^^^^^^^^^^^^^^^^^^^
  File "/home/ubuntu/.cache/pypoetry/virtualenvs/eggtart-QxCesdUQ-py3.12/lib/python3.12/site-packages/uvicorn/importer.py", line 19, in import_from_string
    module = importlib.import_module(module_str)
             ^^^^^^^^^^^^^^^^^^^^^^^^^^^^^^^^^^^
  File "/usr/lib/python3.12/importlib/__init__.py", line 90, in import_module
    return _bootstrap._gcd_import(name[level:], package, level)
           ^^^^^^^^^^^^^^^^^^^^^^^^^^^^^^^^^^^^^^^^^^^^^^^^^^^^
  File "<frozen importlib._bootstrap>", line 1387, in _gcd_import
  File "<frozen importlib._bootstrap>", line 1360, in _find_and_load
  File "<frozen importlib._bootstrap>", line 1331, in _find_and_load_unlocked
  File "<frozen importlib._bootstrap>", line 935, in _load_unlocked
  File "<frozen importlib._bootstrap_external>", line 995, in exec_module
  File "<frozen importlib._bootstrap>", line 488, in _call_with_frames_removed
  File "/home/ubuntu/Eggtart-api-backend/src/main.py", line 19, in <module>
    from database import Base, engine
  File "/home/ubuntu/Eggtart-api-backend/src/database.py", line 14, in <module>
    cx_Oracle.init_oracle_client(lib_dir=instant_client_path)
cx_Oracle.DatabaseError: DPI-1047: Cannot locate a 64-bit Oracle Client library: "libnnz19.so: cannot open shared object file: No such file or directory". See https://cx-oracle.readthedocs.io/en/latest/user_guide/installation.html for help
Traceback (most recent call last):
  File "/home/ubuntu/.cache/pypoetry/virtualenvs/eggtart-QxCesdUQ-py3.12/lib/python3.12/site-packages/sqlalchemy/engine/base.py", line 3371, in _wrap_pool_connect
    return fn()
           ^^^^
  File "/home/ubuntu/.cache/pypoetry/virtualenvs/eggtart-QxCesdUQ-py3.12/lib/python3.12/site-packages/sqlalchemy/pool/base.py", line 327, in connect
    return _ConnectionFairy._checkout(self)
           ^^^^^^^^^^^^^^^^^^^^^^^^^^^^^^^^
  File "/home/ubuntu/.cache/pypoetry/virtualenvs/eggtart-QxCesdUQ-py3.12/lib/python3.12/site-packages/sqlalchemy/pool/base.py", line 894, in _checkout
    fairy = _ConnectionRecord.checkout(pool)
            ^^^^^^^^^^^^^^^^^^^^^^^^^^^^^^^^
  File "/home/ubuntu/.cache/pypoetry/virtualenvs/eggtart-QxCesdUQ-py3.12/lib/python3.12/site-packages/sqlalchemy/pool/base.py", line 493, in checkout
    rec = pool._do_get()
          ^^^^^^^^^^^^^^
  File "/home/ubuntu/.cache/pypoetry/virtualenvs/eggtart-QxCesdUQ-py3.12/lib/python3.12/site-packages/sqlalchemy/pool/impl.py", line 145, in _do_get
    with util.safe_reraise():
  File "/home/ubuntu/.cache/pypoetry/virtualenvs/eggtart-QxCesdUQ-py3.12/lib/python3.12/site-packages/sqlalchemy/util/langhelpers.py", line 70, in __exit__
    compat.raise_(
  File "/home/ubuntu/.cache/pypoetry/virtualenvs/eggtart-QxCesdUQ-py3.12/lib/python3.12/site-packages/sqlalchemy/util/compat.py", line 211, in raise_
    raise exception
  File "/home/ubuntu/.cache/pypoetry/virtualenvs/eggtart-QxCesdUQ-py3.12/lib/python3.12/site-packages/sqlalchemy/pool/impl.py", line 143, in _do_get
    return self._create_connection()
           ^^^^^^^^^^^^^^^^^^^^^^^^^
  File "/home/ubuntu/.cache/pypoetry/virtualenvs/eggtart-QxCesdUQ-py3.12/lib/python3.12/site-packages/sqlalchemy/pool/base.py", line 273, in _create_connection
    return _ConnectionRecord(self)
           ^^^^^^^^^^^^^^^^^^^^^^^
  File "/home/ubuntu/.cache/pypoetry/virtualenvs/eggtart-QxCesdUQ-py3.12/lib/python3.12/site-packages/sqlalchemy/pool/base.py", line 388, in __init__
    self.__connect()
  File "/home/ubuntu/.cache/pypoetry/virtualenvs/eggtart-QxCesdUQ-py3.12/lib/python3.12/site-packages/sqlalchemy/pool/base.py", line 690, in __connect
    with util.safe_reraise():
  File "/home/ubuntu/.cache/pypoetry/virtualenvs/eggtart-QxCesdUQ-py3.12/lib/python3.12/site-packages/sqlalchemy/util/langhelpers.py", line 70, in __exit__
    compat.raise_(
  File "/home/ubuntu/.cache/pypoetry/virtualenvs/eggtart-QxCesdUQ-py3.12/lib/python3.12/site-packages/sqlalchemy/util/compat.py", line 211, in raise_
    raise exception
  File "/home/ubuntu/.cache/pypoetry/virtualenvs/eggtart-QxCesdUQ-py3.12/lib/python3.12/site-packages/sqlalchemy/pool/base.py", line 686, in __connect
    self.dbapi_connection = connection = pool._invoke_creator(self)
                                         ^^^^^^^^^^^^^^^^^^^^^^^^^^
  File "/home/ubuntu/.cache/pypoetry/virtualenvs/eggtart-QxCesdUQ-py3.12/lib/python3.12/site-packages/sqlalchemy/engine/create.py", line 574, in connect
    return dialect.connect(*cargs, **cparams)
           ^^^^^^^^^^^^^^^^^^^^^^^^^^^^^^^^^^
  File "/home/ubuntu/.cache/pypoetry/virtualenvs/eggtart-QxCesdUQ-py3.12/lib/python3.12/site-packages/sqlalchemy/engine/default.py", line 598, in connect
    return self.dbapi.connect(*cargs, **cparams)
           ^^^^^^^^^^^^^^^^^^^^^^^^^^^^^^^^^^^^^
cx_Oracle.DatabaseError: DPI-1047: Cannot locate a 64-bit Oracle Client library: "libclntsh.so: cannot open shared object file: No such file or directory". See https://cx-oracle.readthedocs.io/en/latest/user_guide/installation.html for help

The above exception was the direct cause of the following exception:

Traceback (most recent call last):
  File "/home/ubuntu/.cache/pypoetry/virtualenvs/eggtart-QxCesdUQ-py3.12/bin/uvicorn", line 8, in <module>
    sys.exit(main())
             ^^^^^^
  File "/home/ubuntu/.cache/pypoetry/virtualenvs/eggtart-QxCesdUQ-py3.12/lib/python3.12/site-packages/click/core.py", line 1157, in __call__
    return self.main(*args, **kwargs)
           ^^^^^^^^^^^^^^^^^^^^^^^^^^
  File "/home/ubuntu/.cache/pypoetry/virtualenvs/eggtart-QxCesdUQ-py3.12/lib/python3.12/site-packages/click/core.py", line 1078, in main
    rv = self.invoke(ctx)
         ^^^^^^^^^^^^^^^^
  File "/home/ubuntu/.cache/pypoetry/virtualenvs/eggtart-QxCesdUQ-py3.12/lib/python3.12/site-packages/click/core.py", line 1434, in invoke
    return ctx.invoke(self.callback, **ctx.params)
           ^^^^^^^^^^^^^^^^^^^^^^^^^^^^^^^^^^^^^^^
  File "/home/ubuntu/.cache/pypoetry/virtualenvs/eggtart-QxCesdUQ-py3.12/lib/python3.12/site-packages/click/core.py", line 783, in invoke
    return __callback(*args, **kwargs)
           ^^^^^^^^^^^^^^^^^^^^^^^^^^^
  File "/home/ubuntu/.cache/pypoetry/virtualenvs/eggtart-QxCesdUQ-py3.12/lib/python3.12/site-packages/uvicorn/main.py", line 409, in main
    run(
  File "/home/ubuntu/.cache/pypoetry/virtualenvs/eggtart-QxCesdUQ-py3.12/lib/python3.12/site-packages/uvicorn/main.py", line 575, in run
    server.run()
  File "/home/ubuntu/.cache/pypoetry/virtualenvs/eggtart-QxCesdUQ-py3.12/lib/python3.12/site-packages/uvicorn/server.py", line 62, in run
    return asyncio.run(self.serve(sockets=sockets))
           ^^^^^^^^^^^^^^^^^^^^^^^^^^^^^^^^^^^^^^^^
  File "/usr/lib/python3.12/asyncio/runners.py", line 194, in run
    return runner.run(main)
           ^^^^^^^^^^^^^^^^
  File "/usr/lib/python3.12/asyncio/runners.py", line 118, in run
    return self._loop.run_until_complete(task)
           ^^^^^^^^^^^^^^^^^^^^^^^^^^^^^^^^^^^
  File "/usr/lib/python3.12/asyncio/base_events.py", line 687, in run_until_complete
    return future.result()
           ^^^^^^^^^^^^^^^
  File "/home/ubuntu/.cache/pypoetry/virtualenvs/eggtart-QxCesdUQ-py3.12/lib/python3.12/site-packages/uvicorn/server.py", line 69, in serve
    config.load()
  File "/home/ubuntu/.cache/pypoetry/virtualenvs/eggtart-QxCesdUQ-py3.12/lib/python3.12/site-packages/uvicorn/config.py", line 433, in load
    self.loaded_app = import_from_string(self.app)
                      ^^^^^^^^^^^^^^^^^^^^^^^^^^^^
  File "/home/ubuntu/.cache/pypoetry/virtualenvs/eggtart-QxCesdUQ-py3.12/lib/python3.12/site-packages/uvicorn/importer.py", line 19, in import_from_string
    module = importlib.import_module(module_str)
             ^^^^^^^^^^^^^^^^^^^^^^^^^^^^^^^^^^^
  File "/usr/lib/python3.12/importlib/__init__.py", line 90, in import_module
    return _bootstrap._gcd_import(name[level:], package, level)
           ^^^^^^^^^^^^^^^^^^^^^^^^^^^^^^^^^^^^^^^^^^^^^^^^^^^^
  File "<frozen importlib._bootstrap>", line 1387, in _gcd_import
  File "<frozen importlib._bootstrap>", line 1360, in _find_and_load
  File "<frozen importlib._bootstrap>", line 1331, in _find_and_load_unlocked
  File "<frozen importlib._bootstrap>", line 935, in _load_unlocked
  File "<frozen importlib._bootstrap_external>", line 995, in exec_module
  File "<frozen importlib._bootstrap>", line 488, in _call_with_frames_removed
  File "/home/ubuntu/Eggtart-api-backend/src/main.py", line 28, in <module>
    Base.metadata.create_all(bind=engine)
  File "/home/ubuntu/.cache/pypoetry/virtualenvs/eggtart-QxCesdUQ-py3.12/lib/python3.12/site-packages/sqlalchemy/sql/schema.py", line 4930, in create_all
    bind._run_ddl_visitor(
  File "/home/ubuntu/.cache/pypoetry/virtualenvs/eggtart-QxCesdUQ-py3.12/lib/python3.12/site-packages/sqlalchemy/engine/base.py", line 3237, in _run_ddl_visitor
    with self.begin() as conn:
         ^^^^^^^^^^^^
  File "/home/ubuntu/.cache/pypoetry/virtualenvs/eggtart-QxCesdUQ-py3.12/lib/python3.12/site-packages/sqlalchemy/engine/base.py", line 3153, in begin
    conn = self.connect(close_with_result=close_with_result)
           ^^^^^^^^^^^^^^^^^^^^^^^^^^^^^^^^^^^^^^^^^^^^^^^^^
  File "/home/ubuntu/.cache/pypoetry/virtualenvs/eggtart-QxCesdUQ-py3.12/lib/python3.12/site-packages/sqlalchemy/engine/base.py", line 3325, in connect
    return self._connection_cls(self, close_with_result=close_with_result)
           ^^^^^^^^^^^^^^^^^^^^^^^^^^^^^^^^^^^^^^^^^^^^^^^^^^^^^^^^^^^^^^^
  File "/home/ubuntu/.cache/pypoetry/virtualenvs/eggtart-QxCesdUQ-py3.12/lib/python3.12/site-packages/sqlalchemy/engine/base.py", line 96, in __init__
    else engine.raw_connection()
         ^^^^^^^^^^^^^^^^^^^^^^^
  File "/home/ubuntu/.cache/pypoetry/virtualenvs/eggtart-QxCesdUQ-py3.12/lib/python3.12/site-packages/sqlalchemy/engine/base.py", line 3404, in raw_connection
    return self._wrap_pool_connect(self.pool.connect, _connection)
           ^^^^^^^^^^^^^^^^^^^^^^^^^^^^^^^^^^^^^^^^^^^^^^^^^^^^^^^
  File "/home/ubuntu/.cache/pypoetry/virtualenvs/eggtart-QxCesdUQ-py3.12/lib/python3.12/site-packages/sqlalchemy/engine/base.py", line 3374, in _wrap_pool_connect
    Connection._handle_dbapi_exception_noconnection(
  File "/home/ubuntu/.cache/pypoetry/virtualenvs/eggtart-QxCesdUQ-py3.12/lib/python3.12/site-packages/sqlalchemy/engine/base.py", line 2208, in _handle_dbapi_exception_noconnection
    util.raise_(
  File "/home/ubuntu/.cache/pypoetry/virtualenvs/eggtart-QxCesdUQ-py3.12/lib/python3.12/site-packages/sqlalchemy/util/compat.py", line 211, in raise_
    raise exception
  File "/home/ubuntu/.cache/pypoetry/virtualenvs/eggtart-QxCesdUQ-py3.12/lib/python3.12/site-packages/sqlalchemy/engine/base.py", line 3371, in _wrap_pool_connect
    return fn()
           ^^^^
  File "/home/ubuntu/.cache/pypoetry/virtualenvs/eggtart-QxCesdUQ-py3.12/lib/python3.12/site-packages/sqlalchemy/pool/base.py", line 327, in connect
    return _ConnectionFairy._checkout(self)
           ^^^^^^^^^^^^^^^^^^^^^^^^^^^^^^^^
  File "/home/ubuntu/.cache/pypoetry/virtualenvs/eggtart-QxCesdUQ-py3.12/lib/python3.12/site-packages/sqlalchemy/pool/base.py", line 894, in _checkout
    fairy = _ConnectionRecord.checkout(pool)
            ^^^^^^^^^^^^^^^^^^^^^^^^^^^^^^^^
  File "/home/ubuntu/.cache/pypoetry/virtualenvs/eggtart-QxCesdUQ-py3.12/lib/python3.12/site-packages/sqlalchemy/pool/base.py", line 493, in checkout
    rec = pool._do_get()
          ^^^^^^^^^^^^^^
  File "/home/ubuntu/.cache/pypoetry/virtualenvs/eggtart-QxCesdUQ-py3.12/lib/python3.12/site-packages/sqlalchemy/pool/impl.py", line 145, in _do_get
    with util.safe_reraise():
  File "/home/ubuntu/.cache/pypoetry/virtualenvs/eggtart-QxCesdUQ-py3.12/lib/python3.12/site-packages/sqlalchemy/util/langhelpers.py", line 70, in __exit__
    compat.raise_(
  File "/home/ubuntu/.cache/pypoetry/virtualenvs/eggtart-QxCesdUQ-py3.12/lib/python3.12/site-packages/sqlalchemy/util/compat.py", line 211, in raise_
    raise exception
  File "/home/ubuntu/.cache/pypoetry/virtualenvs/eggtart-QxCesdUQ-py3.12/lib/python3.12/site-packages/sqlalchemy/pool/impl.py", line 143, in _do_get
    return self._create_connection()
           ^^^^^^^^^^^^^^^^^^^^^^^^^
  File "/home/ubuntu/.cache/pypoetry/virtualenvs/eggtart-QxCesdUQ-py3.12/lib/python3.12/site-packages/sqlalchemy/pool/base.py", line 273, in _create_connection
    return _ConnectionRecord(self)
           ^^^^^^^^^^^^^^^^^^^^^^^
  File "/home/ubuntu/.cache/pypoetry/virtualenvs/eggtart-QxCesdUQ-py3.12/lib/python3.12/site-packages/sqlalchemy/pool/base.py", line 388, in __init__
    self.__connect()
  File "/home/ubuntu/.cache/pypoetry/virtualenvs/eggtart-QxCesdUQ-py3.12/lib/python3.12/site-packages/sqlalchemy/pool/base.py", line 690, in __connect
    with util.safe_reraise():
  File "/home/ubuntu/.cache/pypoetry/virtualenvs/eggtart-QxCesdUQ-py3.12/lib/python3.12/site-packages/sqlalchemy/util/langhelpers.py", line 70, in __exit__
    compat.raise_(
  File "/home/ubuntu/.cache/pypoetry/virtualenvs/eggtart-QxCesdUQ-py3.12/lib/python3.12/site-packages/sqlalchemy/util/compat.py", line 211, in raise_
    raise exception
  File "/home/ubuntu/.cache/pypoetry/virtualenvs/eggtart-QxCesdUQ-py3.12/lib/python3.12/site-packages/sqlalchemy/pool/base.py", line 686, in __connect
    self.dbapi_connection = connection = pool._invoke_creator(self)
                                         ^^^^^^^^^^^^^^^^^^^^^^^^^^
  File "/home/ubuntu/.cache/pypoetry/virtualenvs/eggtart-QxCesdUQ-py3.12/lib/python3.12/site-packages/sqlalchemy/engine/create.py", line 574, in connect
    return dialect.connect(*cargs, **cparams)
           ^^^^^^^^^^^^^^^^^^^^^^^^^^^^^^^^^^
  File "/home/ubuntu/.cache/pypoetry/virtualenvs/eggtart-QxCesdUQ-py3.12/lib/python3.12/site-packages/sqlalchemy/engine/default.py", line 598, in connect
    return self.dbapi.connect(*cargs, **cparams)
           ^^^^^^^^^^^^^^^^^^^^^^^^^^^^^^^^^^^^^
sqlalchemy.exc.DatabaseError: (cx_Oracle.DatabaseError) DPI-1047: Cannot locate a 64-bit Oracle Client library: "libclntsh.so: cannot open shared object file: No such file or directory". See https://cx-oracle.readthedocs.io/en/latest/user_guide/installation.html for help
(Background on this error at: https://sqlalche.me/e/14/4xp6)
INFO:     Started server process [1359635]
INFO:     Waiting for application startup.
INFO:     Application startup complete.
ERROR:    [Errno 13] error while attempting to bind on address ('0.0.0.0', 80): permission denied
INFO:     Waiting for application shutdown.
INFO:     Application shutdown complete.
INFO:     Started server process [1359694]
INFO:     Waiting for application startup.
INFO:     Application startup complete.
INFO:     Uvicorn running on http://0.0.0.0:8000 (Press CTRL+C to quit)
INFO:     127.0.0.1:52116 - "GET / HTTP/1.1" 200 OK
INFO:     162.158.186.236:0 - "GET /docs HTTP/1.0" 200 OK
INFO:     162.158.186.236:0 - "GET /openapi.json HTTP/1.0" 200 OK
INFO:     162.158.186.236:0 - "GET /docs HTTP/1.0" 200 OK
INFO:     162.158.186.236:0 - "GET /openapi.json HTTP/1.0" 200 OK
INFO:     162.158.186.236:0 - "GET /docs HTTP/1.0" 200 OK
INFO:     162.158.186.236:0 - "GET /openapi.json HTTP/1.0" 200 OK
INFO:     162.158.186.236:0 - "GET / HTTP/1.0" 200 OK
INFO:     162.158.138.86:0 - "GET / HTTP/1.0" 200 OK
INFO:     172.71.110.199:0 - "GET / HTTP/1.0" 200 OK
INFO:     162.158.186.200:0 - "GET / HTTP/1.0" 200 OK
INFO:     162.158.186.200:0 - "GET / HTTP/1.0" 200 OK
INFO:     172.70.210.80:0 - "GET /docs HTTP/1.0" 200 OK
INFO:     172.70.210.80:0 - "GET /openapi.json HTTP/1.0" 200 OK
INFO:     172.70.210.21:0 - "GET /sheet HTTP/1.0" 401 Unauthorized
INFO:     172.70.210.21:0 - "GET /token HTTP/1.0" 200 OK
INFO:     172.70.210.21:0 - "GET /sheet HTTP/1.0" 401 Unauthorized
INFO:     172.70.210.21:0 - "GET /token HTTP/1.0" 200 OK
INFO:     172.69.33.209:0 - "GET /sheet HTTP/1.0" 401 Unauthorized
INFO:     172.69.33.209:0 - "GET /token HTTP/1.0" 200 OK
INFO:     172.69.33.209:0 - "GET /sheet HTTP/1.0" 200 OK
INFO:     172.69.33.209:0 - "POST /sheet HTTP/1.0" 500 Internal Server Error
ERROR:    Exception in ASGI application
Traceback (most recent call last):
  File "/home/ubuntu/.cache/pypoetry/virtualenvs/eggtart-QxCesdUQ-py3.12/lib/python3.12/site-packages/sqlalchemy/engine/base.py", line 1910, in _execute_context
    self.dialect.do_execute(
  File "/home/ubuntu/.cache/pypoetry/virtualenvs/eggtart-QxCesdUQ-py3.12/lib/python3.12/site-packages/sqlalchemy/engine/default.py", line 736, in do_execute
    cursor.execute(statement, parameters)
cx_Oracle.DatabaseError: ORA-01950: no privileges on tablespace 'DATA'

The above exception was the direct cause of the following exception:

Traceback (most recent call last):
  File "/home/ubuntu/.cache/pypoetry/virtualenvs/eggtart-QxCesdUQ-py3.12/lib/python3.12/site-packages/uvicorn/protocols/http/h11_impl.py", line 407, in run_asgi
    result = await app(  # type: ignore[func-returns-value]
             ^^^^^^^^^^^^^^^^^^^^^^^^^^^^^^^^^^^^^^^^^^^^^^
  File "/home/ubuntu/.cache/pypoetry/virtualenvs/eggtart-QxCesdUQ-py3.12/lib/python3.12/site-packages/uvicorn/middleware/proxy_headers.py", line 69, in __call__
    return await self.app(scope, receive, send)
           ^^^^^^^^^^^^^^^^^^^^^^^^^^^^^^^^^^^^
  File "/home/ubuntu/.cache/pypoetry/virtualenvs/eggtart-QxCesdUQ-py3.12/lib/python3.12/site-packages/fastapi/applications.py", line 1054, in __call__
    await super().__call__(scope, receive, send)
  File "/home/ubuntu/.cache/pypoetry/virtualenvs/eggtart-QxCesdUQ-py3.12/lib/python3.12/site-packages/starlette/applications.py", line 123, in __call__
    await self.middleware_stack(scope, receive, send)
  File "/home/ubuntu/.cache/pypoetry/virtualenvs/eggtart-QxCesdUQ-py3.12/lib/python3.12/site-packages/starlette/middleware/errors.py", line 186, in __call__
    raise exc
  File "/home/ubuntu/.cache/pypoetry/virtualenvs/eggtart-QxCesdUQ-py3.12/lib/python3.12/site-packages/starlette/middleware/errors.py", line 164, in __call__
    await self.app(scope, receive, _send)
  File "/home/ubuntu/.cache/pypoetry/virtualenvs/eggtart-QxCesdUQ-py3.12/lib/python3.12/site-packages/starlette/middleware/cors.py", line 85, in __call__
    await self.app(scope, receive, send)
  File "/home/ubuntu/.cache/pypoetry/virtualenvs/eggtart-QxCesdUQ-py3.12/lib/python3.12/site-packages/starlette/middleware/exceptions.py", line 65, in __call__
    await wrap_app_handling_exceptions(self.app, conn)(scope, receive, send)
  File "/home/ubuntu/.cache/pypoetry/virtualenvs/eggtart-QxCesdUQ-py3.12/lib/python3.12/site-packages/starlette/_exception_handler.py", line 64, in wrapped_app
    raise exc
  File "/home/ubuntu/.cache/pypoetry/virtualenvs/eggtart-QxCesdUQ-py3.12/lib/python3.12/site-packages/starlette/_exception_handler.py", line 53, in wrapped_app
    await app(scope, receive, sender)
  File "/home/ubuntu/.cache/pypoetry/virtualenvs/eggtart-QxCesdUQ-py3.12/lib/python3.12/site-packages/starlette/routing.py", line 756, in __call__
    await self.middleware_stack(scope, receive, send)
  File "/home/ubuntu/.cache/pypoetry/virtualenvs/eggtart-QxCesdUQ-py3.12/lib/python3.12/site-packages/starlette/routing.py", line 776, in app
    await route.handle(scope, receive, send)
  File "/home/ubuntu/.cache/pypoetry/virtualenvs/eggtart-QxCesdUQ-py3.12/lib/python3.12/site-packages/starlette/routing.py", line 297, in handle
    await self.app(scope, receive, send)
  File "/home/ubuntu/.cache/pypoetry/virtualenvs/eggtart-QxCesdUQ-py3.12/lib/python3.12/site-packages/starlette/routing.py", line 77, in app
    await wrap_app_handling_exceptions(app, request)(scope, receive, send)
  File "/home/ubuntu/.cache/pypoetry/virtualenvs/eggtart-QxCesdUQ-py3.12/lib/python3.12/site-packages/starlette/_exception_handler.py", line 64, in wrapped_app
    raise exc
  File "/home/ubuntu/.cache/pypoetry/virtualenvs/eggtart-QxCesdUQ-py3.12/lib/python3.12/site-packages/starlette/_exception_handler.py", line 53, in wrapped_app
    await app(scope, receive, sender)
  File "/home/ubuntu/.cache/pypoetry/virtualenvs/eggtart-QxCesdUQ-py3.12/lib/python3.12/site-packages/starlette/routing.py", line 72, in app
    response = await func(request)
               ^^^^^^^^^^^^^^^^^^^
  File "/home/ubuntu/.cache/pypoetry/virtualenvs/eggtart-QxCesdUQ-py3.12/lib/python3.12/site-packages/fastapi/routing.py", line 278, in app
    raw_response = await run_endpoint_function(
                   ^^^^^^^^^^^^^^^^^^^^^^^^^^^^
  File "/home/ubuntu/.cache/pypoetry/virtualenvs/eggtart-QxCesdUQ-py3.12/lib/python3.12/site-packages/fastapi/routing.py", line 193, in run_endpoint_function
    return await run_in_threadpool(dependant.call, **values)
           ^^^^^^^^^^^^^^^^^^^^^^^^^^^^^^^^^^^^^^^^^^^^^^^^^
  File "/home/ubuntu/.cache/pypoetry/virtualenvs/eggtart-QxCesdUQ-py3.12/lib/python3.12/site-packages/starlette/concurrency.py", line 42, in run_in_threadpool
    return await anyio.to_thread.run_sync(func, *args)
           ^^^^^^^^^^^^^^^^^^^^^^^^^^^^^^^^^^^^^^^^^^^
  File "/home/ubuntu/.cache/pypoetry/virtualenvs/eggtart-QxCesdUQ-py3.12/lib/python3.12/site-packages/anyio/to_thread.py", line 56, in run_sync
    return await get_async_backend().run_sync_in_worker_thread(
           ^^^^^^^^^^^^^^^^^^^^^^^^^^^^^^^^^^^^^^^^^^^^^^^^^^^^
  File "/home/ubuntu/.cache/pypoetry/virtualenvs/eggtart-QxCesdUQ-py3.12/lib/python3.12/site-packages/anyio/_backends/_asyncio.py", line 2177, in run_sync_in_worker_thread
    return await future
           ^^^^^^^^^^^^
  File "/home/ubuntu/.cache/pypoetry/virtualenvs/eggtart-QxCesdUQ-py3.12/lib/python3.12/site-packages/anyio/_backends/_asyncio.py", line 859, in run
    result = context.run(func, *args)
             ^^^^^^^^^^^^^^^^^^^^^^^^
  File "/home/ubuntu/Eggtart-api-backend/src/views/sheet.py", line 21, in create_sheet
    created_sheet = self.sheet_service.create_sheet(dto, user_id)
                    ^^^^^^^^^^^^^^^^^^^^^^^^^^^^^^^^^^^^^^^^^^^^^
  File "/home/ubuntu/Eggtart-api-backend/src/services/sheet.py", line 38, in create_sheet
    with self.transaction:
  File "/home/ubuntu/Eggtart-api-backend/src/transaction.py", line 20, in __exit__
    self.db.commit()
  File "/home/ubuntu/.cache/pypoetry/virtualenvs/eggtart-QxCesdUQ-py3.12/lib/python3.12/site-packages/sqlalchemy/orm/session.py", line 1454, in commit
    self._transaction.commit(_to_root=self.future)
  File "/home/ubuntu/.cache/pypoetry/virtualenvs/eggtart-QxCesdUQ-py3.12/lib/python3.12/site-packages/sqlalchemy/orm/session.py", line 832, in commit
    self._prepare_impl()
  File "/home/ubuntu/.cache/pypoetry/virtualenvs/eggtart-QxCesdUQ-py3.12/lib/python3.12/site-packages/sqlalchemy/orm/session.py", line 811, in _prepare_impl
    self.session.flush()
  File "/home/ubuntu/.cache/pypoetry/virtualenvs/eggtart-QxCesdUQ-py3.12/lib/python3.12/site-packages/sqlalchemy/orm/session.py", line 3449, in flush
    self._flush(objects)
  File "/home/ubuntu/.cache/pypoetry/virtualenvs/eggtart-QxCesdUQ-py3.12/lib/python3.12/site-packages/sqlalchemy/orm/session.py", line 3588, in _flush
    with util.safe_reraise():
  File "/home/ubuntu/.cache/pypoetry/virtualenvs/eggtart-QxCesdUQ-py3.12/lib/python3.12/site-packages/sqlalchemy/util/langhelpers.py", line 70, in __exit__
    compat.raise_(
  File "/home/ubuntu/.cache/pypoetry/virtualenvs/eggtart-QxCesdUQ-py3.12/lib/python3.12/site-packages/sqlalchemy/util/compat.py", line 211, in raise_
    raise exception
  File "/home/ubuntu/.cache/pypoetry/virtualenvs/eggtart-QxCesdUQ-py3.12/lib/python3.12/site-packages/sqlalchemy/orm/session.py", line 3549, in _flush
    flush_context.execute()
  File "/home/ubuntu/.cache/pypoetry/virtualenvs/eggtart-QxCesdUQ-py3.12/lib/python3.12/site-packages/sqlalchemy/orm/unitofwork.py", line 453, in execute
    n.execute_aggregate(self, set_)
  File "/home/ubuntu/.cache/pypoetry/virtualenvs/eggtart-QxCesdUQ-py3.12/lib/python3.12/site-packages/sqlalchemy/orm/unitofwork.py", line 555, in execute_aggregate
    self.execute(uow)
  File "/home/ubuntu/.cache/pypoetry/virtualenvs/eggtart-QxCesdUQ-py3.12/lib/python3.12/site-packages/sqlalchemy/orm/unitofwork.py", line 630, in execute
    util.preloaded.orm_persistence.save_obj(
  File "/home/ubuntu/.cache/pypoetry/virtualenvs/eggtart-QxCesdUQ-py3.12/lib/python3.12/site-packages/sqlalchemy/orm/persistence.py", line 245, in save_obj
    _emit_insert_statements(
  File "/home/ubuntu/.cache/pypoetry/virtualenvs/eggtart-QxCesdUQ-py3.12/lib/python3.12/site-packages/sqlalchemy/orm/persistence.py", line 1238, in _emit_insert_statements
    result = connection._execute_20(
             ^^^^^^^^^^^^^^^^^^^^^^^
  File "/home/ubuntu/.cache/pypoetry/virtualenvs/eggtart-QxCesdUQ-py3.12/lib/python3.12/site-packages/sqlalchemy/engine/base.py", line 1710, in _execute_20
    return meth(self, args_10style, kwargs_10style, execution_options)
           ^^^^^^^^^^^^^^^^^^^^^^^^^^^^^^^^^^^^^^^^^^^^^^^^^^^^^^^^^^^
  File "/home/ubuntu/.cache/pypoetry/virtualenvs/eggtart-QxCesdUQ-py3.12/lib/python3.12/site-packages/sqlalchemy/sql/elements.py", line 334, in _execute_on_connection
    return connection._execute_clauseelement(
           ^^^^^^^^^^^^^^^^^^^^^^^^^^^^^^^^^^
  File "/home/ubuntu/.cache/pypoetry/virtualenvs/eggtart-QxCesdUQ-py3.12/lib/python3.12/site-packages/sqlalchemy/engine/base.py", line 1577, in _execute_clauseelement
    ret = self._execute_context(
          ^^^^^^^^^^^^^^^^^^^^^^
  File "/home/ubuntu/.cache/pypoetry/virtualenvs/eggtart-QxCesdUQ-py3.12/lib/python3.12/site-packages/sqlalchemy/engine/base.py", line 1953, in _execute_context
    self._handle_dbapi_exception(
  File "/home/ubuntu/.cache/pypoetry/virtualenvs/eggtart-QxCesdUQ-py3.12/lib/python3.12/site-packages/sqlalchemy/engine/base.py", line 2134, in _handle_dbapi_exception
    util.raise_(
  File "/home/ubuntu/.cache/pypoetry/virtualenvs/eggtart-QxCesdUQ-py3.12/lib/python3.12/site-packages/sqlalchemy/util/compat.py", line 211, in raise_
    raise exception
  File "/home/ubuntu/.cache/pypoetry/virtualenvs/eggtart-QxCesdUQ-py3.12/lib/python3.12/site-packages/sqlalchemy/engine/base.py", line 1910, in _execute_context
    self.dialect.do_execute(
  File "/home/ubuntu/.cache/pypoetry/virtualenvs/eggtart-QxCesdUQ-py3.12/lib/python3.12/site-packages/sqlalchemy/engine/default.py", line 736, in do_execute
    cursor.execute(statement, parameters)
sqlalchemy.exc.DatabaseError: (cx_Oracle.DatabaseError) ORA-01950: no privileges on tablespace 'DATA'
[SQL: INSERT INTO sheets (owner_id, name, created_at, modified_at) VALUES (:owner_id, :name, :created_at, :modified_at) RETURNING sheets.id INTO :ret_0]
[parameters: {'owner_id': 4, 'name': '', 'created_at': datetime.datetime(2024, 5, 30, 5, 18, 6, 827539), 'modified_at': None, 'ret_0': <cx_Oracle.Var of type DB_TYPE_VARCHAR with value [[], [], [], [], [], [], [], [], [], [], [], [], [], [], [], [], [], [], [], [], [], [], [], [], [], [], [], [], [], [], [], [], [], [], [], [], [], [], [], [], [], [], [], [], [], [], [], [], [], []]>}]
(Background on this error at: https://sqlalche.me/e/14/4xp6)
INFO:     172.69.33.209:0 - "GET /sheet HTTP/1.0" 200 OK
INFO:     172.69.33.209:0 - "POST /sheet HTTP/1.0" 500 Internal Server Error
ERROR:    Exception in ASGI application
Traceback (most recent call last):
  File "/home/ubuntu/.cache/pypoetry/virtualenvs/eggtart-QxCesdUQ-py3.12/lib/python3.12/site-packages/sqlalchemy/engine/base.py", line 1910, in _execute_context
    self.dialect.do_execute(
  File "/home/ubuntu/.cache/pypoetry/virtualenvs/eggtart-QxCesdUQ-py3.12/lib/python3.12/site-packages/sqlalchemy/engine/default.py", line 736, in do_execute
    cursor.execute(statement, parameters)
cx_Oracle.DatabaseError: ORA-01950: no privileges on tablespace 'DATA'

The above exception was the direct cause of the following exception:

Traceback (most recent call last):
  File "/home/ubuntu/.cache/pypoetry/virtualenvs/eggtart-QxCesdUQ-py3.12/lib/python3.12/site-packages/uvicorn/protocols/http/h11_impl.py", line 407, in run_asgi
    result = await app(  # type: ignore[func-returns-value]
             ^^^^^^^^^^^^^^^^^^^^^^^^^^^^^^^^^^^^^^^^^^^^^^
  File "/home/ubuntu/.cache/pypoetry/virtualenvs/eggtart-QxCesdUQ-py3.12/lib/python3.12/site-packages/uvicorn/middleware/proxy_headers.py", line 69, in __call__
    return await self.app(scope, receive, send)
           ^^^^^^^^^^^^^^^^^^^^^^^^^^^^^^^^^^^^
  File "/home/ubuntu/.cache/pypoetry/virtualenvs/eggtart-QxCesdUQ-py3.12/lib/python3.12/site-packages/fastapi/applications.py", line 1054, in __call__
    await super().__call__(scope, receive, send)
  File "/home/ubuntu/.cache/pypoetry/virtualenvs/eggtart-QxCesdUQ-py3.12/lib/python3.12/site-packages/starlette/applications.py", line 123, in __call__
    await self.middleware_stack(scope, receive, send)
  File "/home/ubuntu/.cache/pypoetry/virtualenvs/eggtart-QxCesdUQ-py3.12/lib/python3.12/site-packages/starlette/middleware/errors.py", line 186, in __call__
    raise exc
  File "/home/ubuntu/.cache/pypoetry/virtualenvs/eggtart-QxCesdUQ-py3.12/lib/python3.12/site-packages/starlette/middleware/errors.py", line 164, in __call__
    await self.app(scope, receive, _send)
  File "/home/ubuntu/.cache/pypoetry/virtualenvs/eggtart-QxCesdUQ-py3.12/lib/python3.12/site-packages/starlette/middleware/cors.py", line 85, in __call__
    await self.app(scope, receive, send)
  File "/home/ubuntu/.cache/pypoetry/virtualenvs/eggtart-QxCesdUQ-py3.12/lib/python3.12/site-packages/starlette/middleware/exceptions.py", line 65, in __call__
    await wrap_app_handling_exceptions(self.app, conn)(scope, receive, send)
  File "/home/ubuntu/.cache/pypoetry/virtualenvs/eggtart-QxCesdUQ-py3.12/lib/python3.12/site-packages/starlette/_exception_handler.py", line 64, in wrapped_app
    raise exc
  File "/home/ubuntu/.cache/pypoetry/virtualenvs/eggtart-QxCesdUQ-py3.12/lib/python3.12/site-packages/starlette/_exception_handler.py", line 53, in wrapped_app
    await app(scope, receive, sender)
  File "/home/ubuntu/.cache/pypoetry/virtualenvs/eggtart-QxCesdUQ-py3.12/lib/python3.12/site-packages/starlette/routing.py", line 756, in __call__
    await self.middleware_stack(scope, receive, send)
  File "/home/ubuntu/.cache/pypoetry/virtualenvs/eggtart-QxCesdUQ-py3.12/lib/python3.12/site-packages/starlette/routing.py", line 776, in app
    await route.handle(scope, receive, send)
  File "/home/ubuntu/.cache/pypoetry/virtualenvs/eggtart-QxCesdUQ-py3.12/lib/python3.12/site-packages/starlette/routing.py", line 297, in handle
    await self.app(scope, receive, send)
  File "/home/ubuntu/.cache/pypoetry/virtualenvs/eggtart-QxCesdUQ-py3.12/lib/python3.12/site-packages/starlette/routing.py", line 77, in app
    await wrap_app_handling_exceptions(app, request)(scope, receive, send)
  File "/home/ubuntu/.cache/pypoetry/virtualenvs/eggtart-QxCesdUQ-py3.12/lib/python3.12/site-packages/starlette/_exception_handler.py", line 64, in wrapped_app
    raise exc
  File "/home/ubuntu/.cache/pypoetry/virtualenvs/eggtart-QxCesdUQ-py3.12/lib/python3.12/site-packages/starlette/_exception_handler.py", line 53, in wrapped_app
    await app(scope, receive, sender)
  File "/home/ubuntu/.cache/pypoetry/virtualenvs/eggtart-QxCesdUQ-py3.12/lib/python3.12/site-packages/starlette/routing.py", line 72, in app
    response = await func(request)
               ^^^^^^^^^^^^^^^^^^^
  File "/home/ubuntu/.cache/pypoetry/virtualenvs/eggtart-QxCesdUQ-py3.12/lib/python3.12/site-packages/fastapi/routing.py", line 278, in app
    raw_response = await run_endpoint_function(
                   ^^^^^^^^^^^^^^^^^^^^^^^^^^^^
  File "/home/ubuntu/.cache/pypoetry/virtualenvs/eggtart-QxCesdUQ-py3.12/lib/python3.12/site-packages/fastapi/routing.py", line 193, in run_endpoint_function
    return await run_in_threadpool(dependant.call, **values)
           ^^^^^^^^^^^^^^^^^^^^^^^^^^^^^^^^^^^^^^^^^^^^^^^^^
  File "/home/ubuntu/.cache/pypoetry/virtualenvs/eggtart-QxCesdUQ-py3.12/lib/python3.12/site-packages/starlette/concurrency.py", line 42, in run_in_threadpool
    return await anyio.to_thread.run_sync(func, *args)
           ^^^^^^^^^^^^^^^^^^^^^^^^^^^^^^^^^^^^^^^^^^^
  File "/home/ubuntu/.cache/pypoetry/virtualenvs/eggtart-QxCesdUQ-py3.12/lib/python3.12/site-packages/anyio/to_thread.py", line 56, in run_sync
    return await get_async_backend().run_sync_in_worker_thread(
           ^^^^^^^^^^^^^^^^^^^^^^^^^^^^^^^^^^^^^^^^^^^^^^^^^^^^
  File "/home/ubuntu/.cache/pypoetry/virtualenvs/eggtart-QxCesdUQ-py3.12/lib/python3.12/site-packages/anyio/_backends/_asyncio.py", line 2177, in run_sync_in_worker_thread
    return await future
           ^^^^^^^^^^^^
  File "/home/ubuntu/.cache/pypoetry/virtualenvs/eggtart-QxCesdUQ-py3.12/lib/python3.12/site-packages/anyio/_backends/_asyncio.py", line 859, in run
    result = context.run(func, *args)
             ^^^^^^^^^^^^^^^^^^^^^^^^
  File "/home/ubuntu/Eggtart-api-backend/src/views/sheet.py", line 21, in create_sheet
    created_sheet = self.sheet_service.create_sheet(dto, user_id)
                    ^^^^^^^^^^^^^^^^^^^^^^^^^^^^^^^^^^^^^^^^^^^^^
  File "/home/ubuntu/Eggtart-api-backend/src/services/sheet.py", line 38, in create_sheet
    with self.transaction:
  File "/home/ubuntu/Eggtart-api-backend/src/transaction.py", line 20, in __exit__
    self.db.commit()
  File "/home/ubuntu/.cache/pypoetry/virtualenvs/eggtart-QxCesdUQ-py3.12/lib/python3.12/site-packages/sqlalchemy/orm/session.py", line 1454, in commit
    self._transaction.commit(_to_root=self.future)
  File "/home/ubuntu/.cache/pypoetry/virtualenvs/eggtart-QxCesdUQ-py3.12/lib/python3.12/site-packages/sqlalchemy/orm/session.py", line 832, in commit
    self._prepare_impl()
  File "/home/ubuntu/.cache/pypoetry/virtualenvs/eggtart-QxCesdUQ-py3.12/lib/python3.12/site-packages/sqlalchemy/orm/session.py", line 811, in _prepare_impl
    self.session.flush()
  File "/home/ubuntu/.cache/pypoetry/virtualenvs/eggtart-QxCesdUQ-py3.12/lib/python3.12/site-packages/sqlalchemy/orm/session.py", line 3449, in flush
    self._flush(objects)
  File "/home/ubuntu/.cache/pypoetry/virtualenvs/eggtart-QxCesdUQ-py3.12/lib/python3.12/site-packages/sqlalchemy/orm/session.py", line 3588, in _flush
    with util.safe_reraise():
  File "/home/ubuntu/.cache/pypoetry/virtualenvs/eggtart-QxCesdUQ-py3.12/lib/python3.12/site-packages/sqlalchemy/util/langhelpers.py", line 70, in __exit__
    compat.raise_(
  File "/home/ubuntu/.cache/pypoetry/virtualenvs/eggtart-QxCesdUQ-py3.12/lib/python3.12/site-packages/sqlalchemy/util/compat.py", line 211, in raise_
    raise exception
  File "/home/ubuntu/.cache/pypoetry/virtualenvs/eggtart-QxCesdUQ-py3.12/lib/python3.12/site-packages/sqlalchemy/orm/session.py", line 3549, in _flush
    flush_context.execute()
  File "/home/ubuntu/.cache/pypoetry/virtualenvs/eggtart-QxCesdUQ-py3.12/lib/python3.12/site-packages/sqlalchemy/orm/unitofwork.py", line 453, in execute
    n.execute_aggregate(self, set_)
  File "/home/ubuntu/.cache/pypoetry/virtualenvs/eggtart-QxCesdUQ-py3.12/lib/python3.12/site-packages/sqlalchemy/orm/unitofwork.py", line 555, in execute_aggregate
    self.execute(uow)
  File "/home/ubuntu/.cache/pypoetry/virtualenvs/eggtart-QxCesdUQ-py3.12/lib/python3.12/site-packages/sqlalchemy/orm/unitofwork.py", line 630, in execute
    util.preloaded.orm_persistence.save_obj(
  File "/home/ubuntu/.cache/pypoetry/virtualenvs/eggtart-QxCesdUQ-py3.12/lib/python3.12/site-packages/sqlalchemy/orm/persistence.py", line 245, in save_obj
    _emit_insert_statements(
  File "/home/ubuntu/.cache/pypoetry/virtualenvs/eggtart-QxCesdUQ-py3.12/lib/python3.12/site-packages/sqlalchemy/orm/persistence.py", line 1238, in _emit_insert_statements
    result = connection._execute_20(
             ^^^^^^^^^^^^^^^^^^^^^^^
  File "/home/ubuntu/.cache/pypoetry/virtualenvs/eggtart-QxCesdUQ-py3.12/lib/python3.12/site-packages/sqlalchemy/engine/base.py", line 1710, in _execute_20
    return meth(self, args_10style, kwargs_10style, execution_options)
           ^^^^^^^^^^^^^^^^^^^^^^^^^^^^^^^^^^^^^^^^^^^^^^^^^^^^^^^^^^^
  File "/home/ubuntu/.cache/pypoetry/virtualenvs/eggtart-QxCesdUQ-py3.12/lib/python3.12/site-packages/sqlalchemy/sql/elements.py", line 334, in _execute_on_connection
    return connection._execute_clauseelement(
           ^^^^^^^^^^^^^^^^^^^^^^^^^^^^^^^^^^
  File "/home/ubuntu/.cache/pypoetry/virtualenvs/eggtart-QxCesdUQ-py3.12/lib/python3.12/site-packages/sqlalchemy/engine/base.py", line 1577, in _execute_clauseelement
    ret = self._execute_context(
          ^^^^^^^^^^^^^^^^^^^^^^
  File "/home/ubuntu/.cache/pypoetry/virtualenvs/eggtart-QxCesdUQ-py3.12/lib/python3.12/site-packages/sqlalchemy/engine/base.py", line 1953, in _execute_context
    self._handle_dbapi_exception(
  File "/home/ubuntu/.cache/pypoetry/virtualenvs/eggtart-QxCesdUQ-py3.12/lib/python3.12/site-packages/sqlalchemy/engine/base.py", line 2134, in _handle_dbapi_exception
    util.raise_(
  File "/home/ubuntu/.cache/pypoetry/virtualenvs/eggtart-QxCesdUQ-py3.12/lib/python3.12/site-packages/sqlalchemy/util/compat.py", line 211, in raise_
    raise exception
  File "/home/ubuntu/.cache/pypoetry/virtualenvs/eggtart-QxCesdUQ-py3.12/lib/python3.12/site-packages/sqlalchemy/engine/base.py", line 1910, in _execute_context
    self.dialect.do_execute(
  File "/home/ubuntu/.cache/pypoetry/virtualenvs/eggtart-QxCesdUQ-py3.12/lib/python3.12/site-packages/sqlalchemy/engine/default.py", line 736, in do_execute
    cursor.execute(statement, parameters)
sqlalchemy.exc.DatabaseError: (cx_Oracle.DatabaseError) ORA-01950: no privileges on tablespace 'DATA'
[SQL: INSERT INTO sheets (owner_id, name, created_at, modified_at) VALUES (:owner_id, :name, :created_at, :modified_at) RETURNING sheets.id INTO :ret_0]
[parameters: {'owner_id': 4, 'name': '', 'created_at': datetime.datetime(2024, 5, 30, 5, 18, 7, 549420), 'modified_at': None, 'ret_0': <cx_Oracle.Var of type DB_TYPE_VARCHAR with value [[], [], [], [], [], [], [], [], [], [], [], [], [], [], [], [], [], [], [], [], [], [], [], [], [], [], [], [], [], [], [], [], [], [], [], [], [], [], [], [], [], [], [], [], [], [], [], [], [], []]>}]
(Background on this error at: https://sqlalche.me/e/14/4xp6)
INFO:     172.69.33.209:0 - "GET /sheet HTTP/1.0" 200 OK
INFO:     172.69.33.209:0 - "POST /sheet HTTP/1.0" 500 Internal Server Error
ERROR:    Exception in ASGI application
Traceback (most recent call last):
  File "/home/ubuntu/.cache/pypoetry/virtualenvs/eggtart-QxCesdUQ-py3.12/lib/python3.12/site-packages/sqlalchemy/engine/base.py", line 1910, in _execute_context
    self.dialect.do_execute(
  File "/home/ubuntu/.cache/pypoetry/virtualenvs/eggtart-QxCesdUQ-py3.12/lib/python3.12/site-packages/sqlalchemy/engine/default.py", line 736, in do_execute
    cursor.execute(statement, parameters)
cx_Oracle.DatabaseError: ORA-01950: no privileges on tablespace 'DATA'

The above exception was the direct cause of the following exception:

Traceback (most recent call last):
  File "/home/ubuntu/.cache/pypoetry/virtualenvs/eggtart-QxCesdUQ-py3.12/lib/python3.12/site-packages/uvicorn/protocols/http/h11_impl.py", line 407, in run_asgi
    result = await app(  # type: ignore[func-returns-value]
             ^^^^^^^^^^^^^^^^^^^^^^^^^^^^^^^^^^^^^^^^^^^^^^
  File "/home/ubuntu/.cache/pypoetry/virtualenvs/eggtart-QxCesdUQ-py3.12/lib/python3.12/site-packages/uvicorn/middleware/proxy_headers.py", line 69, in __call__
    return await self.app(scope, receive, send)
           ^^^^^^^^^^^^^^^^^^^^^^^^^^^^^^^^^^^^
  File "/home/ubuntu/.cache/pypoetry/virtualenvs/eggtart-QxCesdUQ-py3.12/lib/python3.12/site-packages/fastapi/applications.py", line 1054, in __call__
    await super().__call__(scope, receive, send)
  File "/home/ubuntu/.cache/pypoetry/virtualenvs/eggtart-QxCesdUQ-py3.12/lib/python3.12/site-packages/starlette/applications.py", line 123, in __call__
    await self.middleware_stack(scope, receive, send)
  File "/home/ubuntu/.cache/pypoetry/virtualenvs/eggtart-QxCesdUQ-py3.12/lib/python3.12/site-packages/starlette/middleware/errors.py", line 186, in __call__
    raise exc
  File "/home/ubuntu/.cache/pypoetry/virtualenvs/eggtart-QxCesdUQ-py3.12/lib/python3.12/site-packages/starlette/middleware/errors.py", line 164, in __call__
    await self.app(scope, receive, _send)
  File "/home/ubuntu/.cache/pypoetry/virtualenvs/eggtart-QxCesdUQ-py3.12/lib/python3.12/site-packages/starlette/middleware/cors.py", line 85, in __call__
    await self.app(scope, receive, send)
  File "/home/ubuntu/.cache/pypoetry/virtualenvs/eggtart-QxCesdUQ-py3.12/lib/python3.12/site-packages/starlette/middleware/exceptions.py", line 65, in __call__
    await wrap_app_handling_exceptions(self.app, conn)(scope, receive, send)
  File "/home/ubuntu/.cache/pypoetry/virtualenvs/eggtart-QxCesdUQ-py3.12/lib/python3.12/site-packages/starlette/_exception_handler.py", line 64, in wrapped_app
    raise exc
  File "/home/ubuntu/.cache/pypoetry/virtualenvs/eggtart-QxCesdUQ-py3.12/lib/python3.12/site-packages/starlette/_exception_handler.py", line 53, in wrapped_app
    await app(scope, receive, sender)
  File "/home/ubuntu/.cache/pypoetry/virtualenvs/eggtart-QxCesdUQ-py3.12/lib/python3.12/site-packages/starlette/routing.py", line 756, in __call__
    await self.middleware_stack(scope, receive, send)
  File "/home/ubuntu/.cache/pypoetry/virtualenvs/eggtart-QxCesdUQ-py3.12/lib/python3.12/site-packages/starlette/routing.py", line 776, in app
    await route.handle(scope, receive, send)
  File "/home/ubuntu/.cache/pypoetry/virtualenvs/eggtart-QxCesdUQ-py3.12/lib/python3.12/site-packages/starlette/routing.py", line 297, in handle
    await self.app(scope, receive, send)
  File "/home/ubuntu/.cache/pypoetry/virtualenvs/eggtart-QxCesdUQ-py3.12/lib/python3.12/site-packages/starlette/routing.py", line 77, in app
    await wrap_app_handling_exceptions(app, request)(scope, receive, send)
  File "/home/ubuntu/.cache/pypoetry/virtualenvs/eggtart-QxCesdUQ-py3.12/lib/python3.12/site-packages/starlette/_exception_handler.py", line 64, in wrapped_app
    raise exc
  File "/home/ubuntu/.cache/pypoetry/virtualenvs/eggtart-QxCesdUQ-py3.12/lib/python3.12/site-packages/starlette/_exception_handler.py", line 53, in wrapped_app
    await app(scope, receive, sender)
  File "/home/ubuntu/.cache/pypoetry/virtualenvs/eggtart-QxCesdUQ-py3.12/lib/python3.12/site-packages/starlette/routing.py", line 72, in app
    response = await func(request)
               ^^^^^^^^^^^^^^^^^^^
  File "/home/ubuntu/.cache/pypoetry/virtualenvs/eggtart-QxCesdUQ-py3.12/lib/python3.12/site-packages/fastapi/routing.py", line 278, in app
    raw_response = await run_endpoint_function(
                   ^^^^^^^^^^^^^^^^^^^^^^^^^^^^
  File "/home/ubuntu/.cache/pypoetry/virtualenvs/eggtart-QxCesdUQ-py3.12/lib/python3.12/site-packages/fastapi/routing.py", line 193, in run_endpoint_function
    return await run_in_threadpool(dependant.call, **values)
           ^^^^^^^^^^^^^^^^^^^^^^^^^^^^^^^^^^^^^^^^^^^^^^^^^
  File "/home/ubuntu/.cache/pypoetry/virtualenvs/eggtart-QxCesdUQ-py3.12/lib/python3.12/site-packages/starlette/concurrency.py", line 42, in run_in_threadpool
    return await anyio.to_thread.run_sync(func, *args)
           ^^^^^^^^^^^^^^^^^^^^^^^^^^^^^^^^^^^^^^^^^^^
  File "/home/ubuntu/.cache/pypoetry/virtualenvs/eggtart-QxCesdUQ-py3.12/lib/python3.12/site-packages/anyio/to_thread.py", line 56, in run_sync
    return await get_async_backend().run_sync_in_worker_thread(
           ^^^^^^^^^^^^^^^^^^^^^^^^^^^^^^^^^^^^^^^^^^^^^^^^^^^^
  File "/home/ubuntu/.cache/pypoetry/virtualenvs/eggtart-QxCesdUQ-py3.12/lib/python3.12/site-packages/anyio/_backends/_asyncio.py", line 2177, in run_sync_in_worker_thread
    return await future
           ^^^^^^^^^^^^
  File "/home/ubuntu/.cache/pypoetry/virtualenvs/eggtart-QxCesdUQ-py3.12/lib/python3.12/site-packages/anyio/_backends/_asyncio.py", line 859, in run
    result = context.run(func, *args)
             ^^^^^^^^^^^^^^^^^^^^^^^^
  File "/home/ubuntu/Eggtart-api-backend/src/views/sheet.py", line 21, in create_sheet
    created_sheet = self.sheet_service.create_sheet(dto, user_id)
                    ^^^^^^^^^^^^^^^^^^^^^^^^^^^^^^^^^^^^^^^^^^^^^
  File "/home/ubuntu/Eggtart-api-backend/src/services/sheet.py", line 38, in create_sheet
    with self.transaction:
  File "/home/ubuntu/Eggtart-api-backend/src/transaction.py", line 20, in __exit__
    self.db.commit()
  File "/home/ubuntu/.cache/pypoetry/virtualenvs/eggtart-QxCesdUQ-py3.12/lib/python3.12/site-packages/sqlalchemy/orm/session.py", line 1454, in commit
    self._transaction.commit(_to_root=self.future)
  File "/home/ubuntu/.cache/pypoetry/virtualenvs/eggtart-QxCesdUQ-py3.12/lib/python3.12/site-packages/sqlalchemy/orm/session.py", line 832, in commit
    self._prepare_impl()
  File "/home/ubuntu/.cache/pypoetry/virtualenvs/eggtart-QxCesdUQ-py3.12/lib/python3.12/site-packages/sqlalchemy/orm/session.py", line 811, in _prepare_impl
    self.session.flush()
  File "/home/ubuntu/.cache/pypoetry/virtualenvs/eggtart-QxCesdUQ-py3.12/lib/python3.12/site-packages/sqlalchemy/orm/session.py", line 3449, in flush
    self._flush(objects)
  File "/home/ubuntu/.cache/pypoetry/virtualenvs/eggtart-QxCesdUQ-py3.12/lib/python3.12/site-packages/sqlalchemy/orm/session.py", line 3588, in _flush
    with util.safe_reraise():
  File "/home/ubuntu/.cache/pypoetry/virtualenvs/eggtart-QxCesdUQ-py3.12/lib/python3.12/site-packages/sqlalchemy/util/langhelpers.py", line 70, in __exit__
    compat.raise_(
  File "/home/ubuntu/.cache/pypoetry/virtualenvs/eggtart-QxCesdUQ-py3.12/lib/python3.12/site-packages/sqlalchemy/util/compat.py", line 211, in raise_
    raise exception
  File "/home/ubuntu/.cache/pypoetry/virtualenvs/eggtart-QxCesdUQ-py3.12/lib/python3.12/site-packages/sqlalchemy/orm/session.py", line 3549, in _flush
    flush_context.execute()
  File "/home/ubuntu/.cache/pypoetry/virtualenvs/eggtart-QxCesdUQ-py3.12/lib/python3.12/site-packages/sqlalchemy/orm/unitofwork.py", line 453, in execute
    n.execute_aggregate(self, set_)
  File "/home/ubuntu/.cache/pypoetry/virtualenvs/eggtart-QxCesdUQ-py3.12/lib/python3.12/site-packages/sqlalchemy/orm/unitofwork.py", line 555, in execute_aggregate
    self.execute(uow)
  File "/home/ubuntu/.cache/pypoetry/virtualenvs/eggtart-QxCesdUQ-py3.12/lib/python3.12/site-packages/sqlalchemy/orm/unitofwork.py", line 630, in execute
    util.preloaded.orm_persistence.save_obj(
  File "/home/ubuntu/.cache/pypoetry/virtualenvs/eggtart-QxCesdUQ-py3.12/lib/python3.12/site-packages/sqlalchemy/orm/persistence.py", line 245, in save_obj
    _emit_insert_statements(
  File "/home/ubuntu/.cache/pypoetry/virtualenvs/eggtart-QxCesdUQ-py3.12/lib/python3.12/site-packages/sqlalchemy/orm/persistence.py", line 1238, in _emit_insert_statements
    result = connection._execute_20(
             ^^^^^^^^^^^^^^^^^^^^^^^
  File "/home/ubuntu/.cache/pypoetry/virtualenvs/eggtart-QxCesdUQ-py3.12/lib/python3.12/site-packages/sqlalchemy/engine/base.py", line 1710, in _execute_20
    return meth(self, args_10style, kwargs_10style, execution_options)
           ^^^^^^^^^^^^^^^^^^^^^^^^^^^^^^^^^^^^^^^^^^^^^^^^^^^^^^^^^^^
  File "/home/ubuntu/.cache/pypoetry/virtualenvs/eggtart-QxCesdUQ-py3.12/lib/python3.12/site-packages/sqlalchemy/sql/elements.py", line 334, in _execute_on_connection
    return connection._execute_clauseelement(
           ^^^^^^^^^^^^^^^^^^^^^^^^^^^^^^^^^^
  File "/home/ubuntu/.cache/pypoetry/virtualenvs/eggtart-QxCesdUQ-py3.12/lib/python3.12/site-packages/sqlalchemy/engine/base.py", line 1577, in _execute_clauseelement
    ret = self._execute_context(
          ^^^^^^^^^^^^^^^^^^^^^^
  File "/home/ubuntu/.cache/pypoetry/virtualenvs/eggtart-QxCesdUQ-py3.12/lib/python3.12/site-packages/sqlalchemy/engine/base.py", line 1953, in _execute_context
    self._handle_dbapi_exception(
  File "/home/ubuntu/.cache/pypoetry/virtualenvs/eggtart-QxCesdUQ-py3.12/lib/python3.12/site-packages/sqlalchemy/engine/base.py", line 2134, in _handle_dbapi_exception
    util.raise_(
  File "/home/ubuntu/.cache/pypoetry/virtualenvs/eggtart-QxCesdUQ-py3.12/lib/python3.12/site-packages/sqlalchemy/util/compat.py", line 211, in raise_
    raise exception
  File "/home/ubuntu/.cache/pypoetry/virtualenvs/eggtart-QxCesdUQ-py3.12/lib/python3.12/site-packages/sqlalchemy/engine/base.py", line 1910, in _execute_context
    self.dialect.do_execute(
  File "/home/ubuntu/.cache/pypoetry/virtualenvs/eggtart-QxCesdUQ-py3.12/lib/python3.12/site-packages/sqlalchemy/engine/default.py", line 736, in do_execute
    cursor.execute(statement, parameters)
sqlalchemy.exc.DatabaseError: (cx_Oracle.DatabaseError) ORA-01950: no privileges on tablespace 'DATA'
[SQL: INSERT INTO sheets (owner_id, name, created_at, modified_at) VALUES (:owner_id, :name, :created_at, :modified_at) RETURNING sheets.id INTO :ret_0]
[parameters: {'owner_id': 4, 'name': '', 'created_at': datetime.datetime(2024, 5, 30, 5, 18, 10, 667600), 'modified_at': None, 'ret_0': <cx_Oracle.Var of type DB_TYPE_VARCHAR with value [[], [], [], [], [], [], [], [], [], [], [], [], [], [], [], [], [], [], [], [], [], [], [], [], [], [], [], [], [], [], [], [], [], [], [], [], [], [], [], [], [], [], [], [], [], [], [], [], [], []]>}]
(Background on this error at: https://sqlalche.me/e/14/4xp6)
INFO:     172.70.214.55:0 - "GET /user/me HTTP/1.0" 403 Forbidden
INFO:     172.70.210.21:0 - "GET /login/kakao?accessToken=bIcTaY7Ei5j4mu7t-FYhKlYl6DXMb6t7AAAAAQo9dZsAAAGPx--xrCJyl_dg0lnq&short=false HTTP/1.0" 500 Internal Server Error
ERROR:    Exception in ASGI application
Traceback (most recent call last):
  File "/home/ubuntu/.cache/pypoetry/virtualenvs/eggtart-QxCesdUQ-py3.12/lib/python3.12/site-packages/sqlalchemy/engine/base.py", line 1910, in _execute_context
    self.dialect.do_execute(
  File "/home/ubuntu/.cache/pypoetry/virtualenvs/eggtart-QxCesdUQ-py3.12/lib/python3.12/site-packages/sqlalchemy/engine/default.py", line 736, in do_execute
    cursor.execute(statement, parameters)
cx_Oracle.DatabaseError: ORA-01950: no privileges on tablespace 'DATA'

The above exception was the direct cause of the following exception:

Traceback (most recent call last):
  File "/home/ubuntu/.cache/pypoetry/virtualenvs/eggtart-QxCesdUQ-py3.12/lib/python3.12/site-packages/uvicorn/protocols/http/h11_impl.py", line 407, in run_asgi
    result = await app(  # type: ignore[func-returns-value]
             ^^^^^^^^^^^^^^^^^^^^^^^^^^^^^^^^^^^^^^^^^^^^^^
  File "/home/ubuntu/.cache/pypoetry/virtualenvs/eggtart-QxCesdUQ-py3.12/lib/python3.12/site-packages/uvicorn/middleware/proxy_headers.py", line 69, in __call__
    return await self.app(scope, receive, send)
           ^^^^^^^^^^^^^^^^^^^^^^^^^^^^^^^^^^^^
  File "/home/ubuntu/.cache/pypoetry/virtualenvs/eggtart-QxCesdUQ-py3.12/lib/python3.12/site-packages/fastapi/applications.py", line 1054, in __call__
    await super().__call__(scope, receive, send)
  File "/home/ubuntu/.cache/pypoetry/virtualenvs/eggtart-QxCesdUQ-py3.12/lib/python3.12/site-packages/starlette/applications.py", line 123, in __call__
    await self.middleware_stack(scope, receive, send)
  File "/home/ubuntu/.cache/pypoetry/virtualenvs/eggtart-QxCesdUQ-py3.12/lib/python3.12/site-packages/starlette/middleware/errors.py", line 186, in __call__
    raise exc
  File "/home/ubuntu/.cache/pypoetry/virtualenvs/eggtart-QxCesdUQ-py3.12/lib/python3.12/site-packages/starlette/middleware/errors.py", line 164, in __call__
    await self.app(scope, receive, _send)
  File "/home/ubuntu/.cache/pypoetry/virtualenvs/eggtart-QxCesdUQ-py3.12/lib/python3.12/site-packages/starlette/middleware/cors.py", line 85, in __call__
    await self.app(scope, receive, send)
  File "/home/ubuntu/.cache/pypoetry/virtualenvs/eggtart-QxCesdUQ-py3.12/lib/python3.12/site-packages/starlette/middleware/exceptions.py", line 65, in __call__
    await wrap_app_handling_exceptions(self.app, conn)(scope, receive, send)
  File "/home/ubuntu/.cache/pypoetry/virtualenvs/eggtart-QxCesdUQ-py3.12/lib/python3.12/site-packages/starlette/_exception_handler.py", line 64, in wrapped_app
    raise exc
  File "/home/ubuntu/.cache/pypoetry/virtualenvs/eggtart-QxCesdUQ-py3.12/lib/python3.12/site-packages/starlette/_exception_handler.py", line 53, in wrapped_app
    await app(scope, receive, sender)
  File "/home/ubuntu/.cache/pypoetry/virtualenvs/eggtart-QxCesdUQ-py3.12/lib/python3.12/site-packages/starlette/routing.py", line 756, in __call__
    await self.middleware_stack(scope, receive, send)
  File "/home/ubuntu/.cache/pypoetry/virtualenvs/eggtart-QxCesdUQ-py3.12/lib/python3.12/site-packages/starlette/routing.py", line 776, in app
    await route.handle(scope, receive, send)
  File "/home/ubuntu/.cache/pypoetry/virtualenvs/eggtart-QxCesdUQ-py3.12/lib/python3.12/site-packages/starlette/routing.py", line 297, in handle
    await self.app(scope, receive, send)
  File "/home/ubuntu/.cache/pypoetry/virtualenvs/eggtart-QxCesdUQ-py3.12/lib/python3.12/site-packages/starlette/routing.py", line 77, in app
    await wrap_app_handling_exceptions(app, request)(scope, receive, send)
  File "/home/ubuntu/.cache/pypoetry/virtualenvs/eggtart-QxCesdUQ-py3.12/lib/python3.12/site-packages/starlette/_exception_handler.py", line 64, in wrapped_app
    raise exc
  File "/home/ubuntu/.cache/pypoetry/virtualenvs/eggtart-QxCesdUQ-py3.12/lib/python3.12/site-packages/starlette/_exception_handler.py", line 53, in wrapped_app
    await app(scope, receive, sender)
  File "/home/ubuntu/.cache/pypoetry/virtualenvs/eggtart-QxCesdUQ-py3.12/lib/python3.12/site-packages/starlette/routing.py", line 72, in app
    response = await func(request)
               ^^^^^^^^^^^^^^^^^^^
  File "/home/ubuntu/.cache/pypoetry/virtualenvs/eggtart-QxCesdUQ-py3.12/lib/python3.12/site-packages/fastapi/routing.py", line 278, in app
    raw_response = await run_endpoint_function(
                   ^^^^^^^^^^^^^^^^^^^^^^^^^^^^
  File "/home/ubuntu/.cache/pypoetry/virtualenvs/eggtart-QxCesdUQ-py3.12/lib/python3.12/site-packages/fastapi/routing.py", line 193, in run_endpoint_function
    return await run_in_threadpool(dependant.call, **values)
           ^^^^^^^^^^^^^^^^^^^^^^^^^^^^^^^^^^^^^^^^^^^^^^^^^
  File "/home/ubuntu/.cache/pypoetry/virtualenvs/eggtart-QxCesdUQ-py3.12/lib/python3.12/site-packages/starlette/concurrency.py", line 42, in run_in_threadpool
    return await anyio.to_thread.run_sync(func, *args)
           ^^^^^^^^^^^^^^^^^^^^^^^^^^^^^^^^^^^^^^^^^^^
  File "/home/ubuntu/.cache/pypoetry/virtualenvs/eggtart-QxCesdUQ-py3.12/lib/python3.12/site-packages/anyio/to_thread.py", line 56, in run_sync
    return await get_async_backend().run_sync_in_worker_thread(
           ^^^^^^^^^^^^^^^^^^^^^^^^^^^^^^^^^^^^^^^^^^^^^^^^^^^^
  File "/home/ubuntu/.cache/pypoetry/virtualenvs/eggtart-QxCesdUQ-py3.12/lib/python3.12/site-packages/anyio/_backends/_asyncio.py", line 2177, in run_sync_in_worker_thread
    return await future
           ^^^^^^^^^^^^
  File "/home/ubuntu/.cache/pypoetry/virtualenvs/eggtart-QxCesdUQ-py3.12/lib/python3.12/site-packages/anyio/_backends/_asyncio.py", line 859, in run
    result = context.run(func, *args)
             ^^^^^^^^^^^^^^^^^^^^^^^^
  File "/home/ubuntu/Eggtart-api-backend/src/views/login.py", line 27, in kakao_login
    return self.login_service.handle_login(access_token, "KAKAO", short)
           ^^^^^^^^^^^^^^^^^^^^^^^^^^^^^^^^^^^^^^^^^^^^^^^^^^^^^^^^^^^^^
  File "/home/ubuntu/Eggtart-api-backend/src/services/login.py", line 44, in handle_login
    user_id = self.request_kakao_user_info(access_token)
              ^^^^^^^^^^^^^^^^^^^^^^^^^^^^^^^^^^^^^^^^^^
  File "/home/ubuntu/Eggtart-api-backend/src/services/login.py", line 69, in request_kakao_user_info
    with self.transaction:
  File "/home/ubuntu/Eggtart-api-backend/src/transaction.py", line 20, in __exit__
    self.db.commit()
  File "/home/ubuntu/.cache/pypoetry/virtualenvs/eggtart-QxCesdUQ-py3.12/lib/python3.12/site-packages/sqlalchemy/orm/session.py", line 1454, in commit
    self._transaction.commit(_to_root=self.future)
  File "/home/ubuntu/.cache/pypoetry/virtualenvs/eggtart-QxCesdUQ-py3.12/lib/python3.12/site-packages/sqlalchemy/orm/session.py", line 832, in commit
    self._prepare_impl()
  File "/home/ubuntu/.cache/pypoetry/virtualenvs/eggtart-QxCesdUQ-py3.12/lib/python3.12/site-packages/sqlalchemy/orm/session.py", line 811, in _prepare_impl
    self.session.flush()
  File "/home/ubuntu/.cache/pypoetry/virtualenvs/eggtart-QxCesdUQ-py3.12/lib/python3.12/site-packages/sqlalchemy/orm/session.py", line 3449, in flush
    self._flush(objects)
  File "/home/ubuntu/.cache/pypoetry/virtualenvs/eggtart-QxCesdUQ-py3.12/lib/python3.12/site-packages/sqlalchemy/orm/session.py", line 3588, in _flush
    with util.safe_reraise():
  File "/home/ubuntu/.cache/pypoetry/virtualenvs/eggtart-QxCesdUQ-py3.12/lib/python3.12/site-packages/sqlalchemy/util/langhelpers.py", line 70, in __exit__
    compat.raise_(
  File "/home/ubuntu/.cache/pypoetry/virtualenvs/eggtart-QxCesdUQ-py3.12/lib/python3.12/site-packages/sqlalchemy/util/compat.py", line 211, in raise_
    raise exception
  File "/home/ubuntu/.cache/pypoetry/virtualenvs/eggtart-QxCesdUQ-py3.12/lib/python3.12/site-packages/sqlalchemy/orm/session.py", line 3549, in _flush
    flush_context.execute()
  File "/home/ubuntu/.cache/pypoetry/virtualenvs/eggtart-QxCesdUQ-py3.12/lib/python3.12/site-packages/sqlalchemy/orm/unitofwork.py", line 456, in execute
    rec.execute(self)
  File "/home/ubuntu/.cache/pypoetry/virtualenvs/eggtart-QxCesdUQ-py3.12/lib/python3.12/site-packages/sqlalchemy/orm/unitofwork.py", line 630, in execute
    util.preloaded.orm_persistence.save_obj(
  File "/home/ubuntu/.cache/pypoetry/virtualenvs/eggtart-QxCesdUQ-py3.12/lib/python3.12/site-packages/sqlalchemy/orm/persistence.py", line 245, in save_obj
    _emit_insert_statements(
  File "/home/ubuntu/.cache/pypoetry/virtualenvs/eggtart-QxCesdUQ-py3.12/lib/python3.12/site-packages/sqlalchemy/orm/persistence.py", line 1238, in _emit_insert_statements
    result = connection._execute_20(
             ^^^^^^^^^^^^^^^^^^^^^^^
  File "/home/ubuntu/.cache/pypoetry/virtualenvs/eggtart-QxCesdUQ-py3.12/lib/python3.12/site-packages/sqlalchemy/engine/base.py", line 1710, in _execute_20
    return meth(self, args_10style, kwargs_10style, execution_options)
           ^^^^^^^^^^^^^^^^^^^^^^^^^^^^^^^^^^^^^^^^^^^^^^^^^^^^^^^^^^^
  File "/home/ubuntu/.cache/pypoetry/virtualenvs/eggtart-QxCesdUQ-py3.12/lib/python3.12/site-packages/sqlalchemy/sql/elements.py", line 334, in _execute_on_connection
    return connection._execute_clauseelement(
           ^^^^^^^^^^^^^^^^^^^^^^^^^^^^^^^^^^
  File "/home/ubuntu/.cache/pypoetry/virtualenvs/eggtart-QxCesdUQ-py3.12/lib/python3.12/site-packages/sqlalchemy/engine/base.py", line 1577, in _execute_clauseelement
    ret = self._execute_context(
          ^^^^^^^^^^^^^^^^^^^^^^
  File "/home/ubuntu/.cache/pypoetry/virtualenvs/eggtart-QxCesdUQ-py3.12/lib/python3.12/site-packages/sqlalchemy/engine/base.py", line 1953, in _execute_context
    self._handle_dbapi_exception(
  File "/home/ubuntu/.cache/pypoetry/virtualenvs/eggtart-QxCesdUQ-py3.12/lib/python3.12/site-packages/sqlalchemy/engine/base.py", line 2134, in _handle_dbapi_exception
    util.raise_(
  File "/home/ubuntu/.cache/pypoetry/virtualenvs/eggtart-QxCesdUQ-py3.12/lib/python3.12/site-packages/sqlalchemy/util/compat.py", line 211, in raise_
    raise exception
  File "/home/ubuntu/.cache/pypoetry/virtualenvs/eggtart-QxCesdUQ-py3.12/lib/python3.12/site-packages/sqlalchemy/engine/base.py", line 1910, in _execute_context
    self.dialect.do_execute(
  File "/home/ubuntu/.cache/pypoetry/virtualenvs/eggtart-QxCesdUQ-py3.12/lib/python3.12/site-packages/sqlalchemy/engine/default.py", line 736, in do_execute
    cursor.execute(statement, parameters)
sqlalchemy.exc.DatabaseError: (cx_Oracle.DatabaseError) ORA-01950: no privileges on tablespace 'DATA'
[SQL: INSERT INTO users (nickname, social_id, social_provider, apple_refresh_token) VALUES (:nickname, :social_id, :social_provider, :apple_refresh_token) RETURNING users.id INTO :ret_0]
[parameters: {'nickname': '원진', 'social_id': 3424747083, 'social_provider': 'KAKAO', 'apple_refresh_token': None, 'ret_0': <cx_Oracle.Var of type DB_TYPE_VARCHAR with value [[], [], [], [], [], [], [], [], [], [], [], [], [], [], [], [], [], [], [], [], [], [], [], [], [], [], [], [], [], [], [], [], [], [], [], [], [], [], [], [], [], [], [], [], [], [], [], [], [], []]>}]
(Background on this error at: https://sqlalche.me/e/14/4xp6)
INFO:     162.158.186.201:0 - "GET /login/kakao?accessToken=seV41GNnrvyHx2rY0oxmn6cDKRmAZ8MDAAAAAQoqJZAAAAGPx-_-riJyl_dg0lnq&short=false HTTP/1.0" 500 Internal Server Error
ERROR:    Exception in ASGI application
Traceback (most recent call last):
  File "/home/ubuntu/.cache/pypoetry/virtualenvs/eggtart-QxCesdUQ-py3.12/lib/python3.12/site-packages/sqlalchemy/engine/base.py", line 1910, in _execute_context
    self.dialect.do_execute(
  File "/home/ubuntu/.cache/pypoetry/virtualenvs/eggtart-QxCesdUQ-py3.12/lib/python3.12/site-packages/sqlalchemy/engine/default.py", line 736, in do_execute
    cursor.execute(statement, parameters)
cx_Oracle.DatabaseError: ORA-01950: no privileges on tablespace 'DATA'

The above exception was the direct cause of the following exception:

Traceback (most recent call last):
  File "/home/ubuntu/.cache/pypoetry/virtualenvs/eggtart-QxCesdUQ-py3.12/lib/python3.12/site-packages/uvicorn/protocols/http/h11_impl.py", line 407, in run_asgi
    result = await app(  # type: ignore[func-returns-value]
             ^^^^^^^^^^^^^^^^^^^^^^^^^^^^^^^^^^^^^^^^^^^^^^
  File "/home/ubuntu/.cache/pypoetry/virtualenvs/eggtart-QxCesdUQ-py3.12/lib/python3.12/site-packages/uvicorn/middleware/proxy_headers.py", line 69, in __call__
    return await self.app(scope, receive, send)
           ^^^^^^^^^^^^^^^^^^^^^^^^^^^^^^^^^^^^
  File "/home/ubuntu/.cache/pypoetry/virtualenvs/eggtart-QxCesdUQ-py3.12/lib/python3.12/site-packages/fastapi/applications.py", line 1054, in __call__
    await super().__call__(scope, receive, send)
  File "/home/ubuntu/.cache/pypoetry/virtualenvs/eggtart-QxCesdUQ-py3.12/lib/python3.12/site-packages/starlette/applications.py", line 123, in __call__
    await self.middleware_stack(scope, receive, send)
  File "/home/ubuntu/.cache/pypoetry/virtualenvs/eggtart-QxCesdUQ-py3.12/lib/python3.12/site-packages/starlette/middleware/errors.py", line 186, in __call__
    raise exc
  File "/home/ubuntu/.cache/pypoetry/virtualenvs/eggtart-QxCesdUQ-py3.12/lib/python3.12/site-packages/starlette/middleware/errors.py", line 164, in __call__
    await self.app(scope, receive, _send)
  File "/home/ubuntu/.cache/pypoetry/virtualenvs/eggtart-QxCesdUQ-py3.12/lib/python3.12/site-packages/starlette/middleware/cors.py", line 85, in __call__
    await self.app(scope, receive, send)
  File "/home/ubuntu/.cache/pypoetry/virtualenvs/eggtart-QxCesdUQ-py3.12/lib/python3.12/site-packages/starlette/middleware/exceptions.py", line 65, in __call__
    await wrap_app_handling_exceptions(self.app, conn)(scope, receive, send)
  File "/home/ubuntu/.cache/pypoetry/virtualenvs/eggtart-QxCesdUQ-py3.12/lib/python3.12/site-packages/starlette/_exception_handler.py", line 64, in wrapped_app
    raise exc
  File "/home/ubuntu/.cache/pypoetry/virtualenvs/eggtart-QxCesdUQ-py3.12/lib/python3.12/site-packages/starlette/_exception_handler.py", line 53, in wrapped_app
    await app(scope, receive, sender)
  File "/home/ubuntu/.cache/pypoetry/virtualenvs/eggtart-QxCesdUQ-py3.12/lib/python3.12/site-packages/starlette/routing.py", line 756, in __call__
    await self.middleware_stack(scope, receive, send)
  File "/home/ubuntu/.cache/pypoetry/virtualenvs/eggtart-QxCesdUQ-py3.12/lib/python3.12/site-packages/starlette/routing.py", line 776, in app
    await route.handle(scope, receive, send)
  File "/home/ubuntu/.cache/pypoetry/virtualenvs/eggtart-QxCesdUQ-py3.12/lib/python3.12/site-packages/starlette/routing.py", line 297, in handle
    await self.app(scope, receive, send)
  File "/home/ubuntu/.cache/pypoetry/virtualenvs/eggtart-QxCesdUQ-py3.12/lib/python3.12/site-packages/starlette/routing.py", line 77, in app
    await wrap_app_handling_exceptions(app, request)(scope, receive, send)
  File "/home/ubuntu/.cache/pypoetry/virtualenvs/eggtart-QxCesdUQ-py3.12/lib/python3.12/site-packages/starlette/_exception_handler.py", line 64, in wrapped_app
    raise exc
  File "/home/ubuntu/.cache/pypoetry/virtualenvs/eggtart-QxCesdUQ-py3.12/lib/python3.12/site-packages/starlette/_exception_handler.py", line 53, in wrapped_app
    await app(scope, receive, sender)
  File "/home/ubuntu/.cache/pypoetry/virtualenvs/eggtart-QxCesdUQ-py3.12/lib/python3.12/site-packages/starlette/routing.py", line 72, in app
    response = await func(request)
               ^^^^^^^^^^^^^^^^^^^
  File "/home/ubuntu/.cache/pypoetry/virtualenvs/eggtart-QxCesdUQ-py3.12/lib/python3.12/site-packages/fastapi/routing.py", line 278, in app
    raw_response = await run_endpoint_function(
                   ^^^^^^^^^^^^^^^^^^^^^^^^^^^^
  File "/home/ubuntu/.cache/pypoetry/virtualenvs/eggtart-QxCesdUQ-py3.12/lib/python3.12/site-packages/fastapi/routing.py", line 193, in run_endpoint_function
    return await run_in_threadpool(dependant.call, **values)
           ^^^^^^^^^^^^^^^^^^^^^^^^^^^^^^^^^^^^^^^^^^^^^^^^^
  File "/home/ubuntu/.cache/pypoetry/virtualenvs/eggtart-QxCesdUQ-py3.12/lib/python3.12/site-packages/starlette/concurrency.py", line 42, in run_in_threadpool
    return await anyio.to_thread.run_sync(func, *args)
           ^^^^^^^^^^^^^^^^^^^^^^^^^^^^^^^^^^^^^^^^^^^
  File "/home/ubuntu/.cache/pypoetry/virtualenvs/eggtart-QxCesdUQ-py3.12/lib/python3.12/site-packages/anyio/to_thread.py", line 56, in run_sync
    return await get_async_backend().run_sync_in_worker_thread(
           ^^^^^^^^^^^^^^^^^^^^^^^^^^^^^^^^^^^^^^^^^^^^^^^^^^^^
  File "/home/ubuntu/.cache/pypoetry/virtualenvs/eggtart-QxCesdUQ-py3.12/lib/python3.12/site-packages/anyio/_backends/_asyncio.py", line 2177, in run_sync_in_worker_thread
    return await future
           ^^^^^^^^^^^^
  File "/home/ubuntu/.cache/pypoetry/virtualenvs/eggtart-QxCesdUQ-py3.12/lib/python3.12/site-packages/anyio/_backends/_asyncio.py", line 859, in run
    result = context.run(func, *args)
             ^^^^^^^^^^^^^^^^^^^^^^^^
  File "/home/ubuntu/Eggtart-api-backend/src/views/login.py", line 27, in kakao_login
    return self.login_service.handle_login(access_token, "KAKAO", short)
           ^^^^^^^^^^^^^^^^^^^^^^^^^^^^^^^^^^^^^^^^^^^^^^^^^^^^^^^^^^^^^
  File "/home/ubuntu/Eggtart-api-backend/src/services/login.py", line 44, in handle_login
    user_id = self.request_kakao_user_info(access_token)
              ^^^^^^^^^^^^^^^^^^^^^^^^^^^^^^^^^^^^^^^^^^
  File "/home/ubuntu/Eggtart-api-backend/src/services/login.py", line 69, in request_kakao_user_info
    with self.transaction:
  File "/home/ubuntu/Eggtart-api-backend/src/transaction.py", line 20, in __exit__
    self.db.commit()
  File "/home/ubuntu/.cache/pypoetry/virtualenvs/eggtart-QxCesdUQ-py3.12/lib/python3.12/site-packages/sqlalchemy/orm/session.py", line 1454, in commit
    self._transaction.commit(_to_root=self.future)
  File "/home/ubuntu/.cache/pypoetry/virtualenvs/eggtart-QxCesdUQ-py3.12/lib/python3.12/site-packages/sqlalchemy/orm/session.py", line 832, in commit
    self._prepare_impl()
  File "/home/ubuntu/.cache/pypoetry/virtualenvs/eggtart-QxCesdUQ-py3.12/lib/python3.12/site-packages/sqlalchemy/orm/session.py", line 811, in _prepare_impl
    self.session.flush()
  File "/home/ubuntu/.cache/pypoetry/virtualenvs/eggtart-QxCesdUQ-py3.12/lib/python3.12/site-packages/sqlalchemy/orm/session.py", line 3449, in flush
    self._flush(objects)
  File "/home/ubuntu/.cache/pypoetry/virtualenvs/eggtart-QxCesdUQ-py3.12/lib/python3.12/site-packages/sqlalchemy/orm/session.py", line 3588, in _flush
    with util.safe_reraise():
  File "/home/ubuntu/.cache/pypoetry/virtualenvs/eggtart-QxCesdUQ-py3.12/lib/python3.12/site-packages/sqlalchemy/util/langhelpers.py", line 70, in __exit__
    compat.raise_(
  File "/home/ubuntu/.cache/pypoetry/virtualenvs/eggtart-QxCesdUQ-py3.12/lib/python3.12/site-packages/sqlalchemy/util/compat.py", line 211, in raise_
    raise exception
  File "/home/ubuntu/.cache/pypoetry/virtualenvs/eggtart-QxCesdUQ-py3.12/lib/python3.12/site-packages/sqlalchemy/orm/session.py", line 3549, in _flush
    flush_context.execute()
  File "/home/ubuntu/.cache/pypoetry/virtualenvs/eggtart-QxCesdUQ-py3.12/lib/python3.12/site-packages/sqlalchemy/orm/unitofwork.py", line 456, in execute
    rec.execute(self)
  File "/home/ubuntu/.cache/pypoetry/virtualenvs/eggtart-QxCesdUQ-py3.12/lib/python3.12/site-packages/sqlalchemy/orm/unitofwork.py", line 630, in execute
    util.preloaded.orm_persistence.save_obj(
  File "/home/ubuntu/.cache/pypoetry/virtualenvs/eggtart-QxCesdUQ-py3.12/lib/python3.12/site-packages/sqlalchemy/orm/persistence.py", line 245, in save_obj
    _emit_insert_statements(
  File "/home/ubuntu/.cache/pypoetry/virtualenvs/eggtart-QxCesdUQ-py3.12/lib/python3.12/site-packages/sqlalchemy/orm/persistence.py", line 1238, in _emit_insert_statements
    result = connection._execute_20(
             ^^^^^^^^^^^^^^^^^^^^^^^
  File "/home/ubuntu/.cache/pypoetry/virtualenvs/eggtart-QxCesdUQ-py3.12/lib/python3.12/site-packages/sqlalchemy/engine/base.py", line 1710, in _execute_20
    return meth(self, args_10style, kwargs_10style, execution_options)
           ^^^^^^^^^^^^^^^^^^^^^^^^^^^^^^^^^^^^^^^^^^^^^^^^^^^^^^^^^^^
  File "/home/ubuntu/.cache/pypoetry/virtualenvs/eggtart-QxCesdUQ-py3.12/lib/python3.12/site-packages/sqlalchemy/sql/elements.py", line 334, in _execute_on_connection
    return connection._execute_clauseelement(
           ^^^^^^^^^^^^^^^^^^^^^^^^^^^^^^^^^^
  File "/home/ubuntu/.cache/pypoetry/virtualenvs/eggtart-QxCesdUQ-py3.12/lib/python3.12/site-packages/sqlalchemy/engine/base.py", line 1577, in _execute_clauseelement
    ret = self._execute_context(
          ^^^^^^^^^^^^^^^^^^^^^^
  File "/home/ubuntu/.cache/pypoetry/virtualenvs/eggtart-QxCesdUQ-py3.12/lib/python3.12/site-packages/sqlalchemy/engine/base.py", line 1953, in _execute_context
    self._handle_dbapi_exception(
  File "/home/ubuntu/.cache/pypoetry/virtualenvs/eggtart-QxCesdUQ-py3.12/lib/python3.12/site-packages/sqlalchemy/engine/base.py", line 2134, in _handle_dbapi_exception
    util.raise_(
  File "/home/ubuntu/.cache/pypoetry/virtualenvs/eggtart-QxCesdUQ-py3.12/lib/python3.12/site-packages/sqlalchemy/util/compat.py", line 211, in raise_
    raise exception
  File "/home/ubuntu/.cache/pypoetry/virtualenvs/eggtart-QxCesdUQ-py3.12/lib/python3.12/site-packages/sqlalchemy/engine/base.py", line 1910, in _execute_context
    self.dialect.do_execute(
  File "/home/ubuntu/.cache/pypoetry/virtualenvs/eggtart-QxCesdUQ-py3.12/lib/python3.12/site-packages/sqlalchemy/engine/default.py", line 736, in do_execute
    cursor.execute(statement, parameters)
sqlalchemy.exc.DatabaseError: (cx_Oracle.DatabaseError) ORA-01950: no privileges on tablespace 'DATA'
[SQL: INSERT INTO users (nickname, social_id, social_provider, apple_refresh_token) VALUES (:nickname, :social_id, :social_provider, :apple_refresh_token) RETURNING users.id INTO :ret_0]
[parameters: {'nickname': '원진', 'social_id': 3424747083, 'social_provider': 'KAKAO', 'apple_refresh_token': None, 'ret_0': <cx_Oracle.Var of type DB_TYPE_VARCHAR with value [[], [], [], [], [], [], [], [], [], [], [], [], [], [], [], [], [], [], [], [], [], [], [], [], [], [], [], [], [], [], [], [], [], [], [], [], [], [], [], [], [], [], [], [], [], [], [], [], [], []]>}]
(Background on this error at: https://sqlalche.me/e/14/4xp6)
INFO:     172.70.211.110:0 - "GET /login/kakao?accessToken=seV41GNnrvyHx2rY0oxmn6cDKRmAZ8MDAAAAAQoqJZAAAAGPx-_-riJyl_dg0lnq&short=false HTTP/1.0" 500 Internal Server Error
ERROR:    Exception in ASGI application
Traceback (most recent call last):
  File "/home/ubuntu/.cache/pypoetry/virtualenvs/eggtart-QxCesdUQ-py3.12/lib/python3.12/site-packages/sqlalchemy/engine/base.py", line 1910, in _execute_context
    self.dialect.do_execute(
  File "/home/ubuntu/.cache/pypoetry/virtualenvs/eggtart-QxCesdUQ-py3.12/lib/python3.12/site-packages/sqlalchemy/engine/default.py", line 736, in do_execute
    cursor.execute(statement, parameters)
cx_Oracle.DatabaseError: ORA-01950: no privileges on tablespace 'DATA'

The above exception was the direct cause of the following exception:

Traceback (most recent call last):
  File "/home/ubuntu/.cache/pypoetry/virtualenvs/eggtart-QxCesdUQ-py3.12/lib/python3.12/site-packages/uvicorn/protocols/http/h11_impl.py", line 407, in run_asgi
    result = await app(  # type: ignore[func-returns-value]
             ^^^^^^^^^^^^^^^^^^^^^^^^^^^^^^^^^^^^^^^^^^^^^^
  File "/home/ubuntu/.cache/pypoetry/virtualenvs/eggtart-QxCesdUQ-py3.12/lib/python3.12/site-packages/uvicorn/middleware/proxy_headers.py", line 69, in __call__
    return await self.app(scope, receive, send)
           ^^^^^^^^^^^^^^^^^^^^^^^^^^^^^^^^^^^^
  File "/home/ubuntu/.cache/pypoetry/virtualenvs/eggtart-QxCesdUQ-py3.12/lib/python3.12/site-packages/fastapi/applications.py", line 1054, in __call__
    await super().__call__(scope, receive, send)
  File "/home/ubuntu/.cache/pypoetry/virtualenvs/eggtart-QxCesdUQ-py3.12/lib/python3.12/site-packages/starlette/applications.py", line 123, in __call__
    await self.middleware_stack(scope, receive, send)
  File "/home/ubuntu/.cache/pypoetry/virtualenvs/eggtart-QxCesdUQ-py3.12/lib/python3.12/site-packages/starlette/middleware/errors.py", line 186, in __call__
    raise exc
  File "/home/ubuntu/.cache/pypoetry/virtualenvs/eggtart-QxCesdUQ-py3.12/lib/python3.12/site-packages/starlette/middleware/errors.py", line 164, in __call__
    await self.app(scope, receive, _send)
  File "/home/ubuntu/.cache/pypoetry/virtualenvs/eggtart-QxCesdUQ-py3.12/lib/python3.12/site-packages/starlette/middleware/cors.py", line 85, in __call__
    await self.app(scope, receive, send)
  File "/home/ubuntu/.cache/pypoetry/virtualenvs/eggtart-QxCesdUQ-py3.12/lib/python3.12/site-packages/starlette/middleware/exceptions.py", line 65, in __call__
    await wrap_app_handling_exceptions(self.app, conn)(scope, receive, send)
  File "/home/ubuntu/.cache/pypoetry/virtualenvs/eggtart-QxCesdUQ-py3.12/lib/python3.12/site-packages/starlette/_exception_handler.py", line 64, in wrapped_app
    raise exc
  File "/home/ubuntu/.cache/pypoetry/virtualenvs/eggtart-QxCesdUQ-py3.12/lib/python3.12/site-packages/starlette/_exception_handler.py", line 53, in wrapped_app
    await app(scope, receive, sender)
  File "/home/ubuntu/.cache/pypoetry/virtualenvs/eggtart-QxCesdUQ-py3.12/lib/python3.12/site-packages/starlette/routing.py", line 756, in __call__
    await self.middleware_stack(scope, receive, send)
  File "/home/ubuntu/.cache/pypoetry/virtualenvs/eggtart-QxCesdUQ-py3.12/lib/python3.12/site-packages/starlette/routing.py", line 776, in app
    await route.handle(scope, receive, send)
  File "/home/ubuntu/.cache/pypoetry/virtualenvs/eggtart-QxCesdUQ-py3.12/lib/python3.12/site-packages/starlette/routing.py", line 297, in handle
    await self.app(scope, receive, send)
  File "/home/ubuntu/.cache/pypoetry/virtualenvs/eggtart-QxCesdUQ-py3.12/lib/python3.12/site-packages/starlette/routing.py", line 77, in app
    await wrap_app_handling_exceptions(app, request)(scope, receive, send)
  File "/home/ubuntu/.cache/pypoetry/virtualenvs/eggtart-QxCesdUQ-py3.12/lib/python3.12/site-packages/starlette/_exception_handler.py", line 64, in wrapped_app
    raise exc
  File "/home/ubuntu/.cache/pypoetry/virtualenvs/eggtart-QxCesdUQ-py3.12/lib/python3.12/site-packages/starlette/_exception_handler.py", line 53, in wrapped_app
    await app(scope, receive, sender)
  File "/home/ubuntu/.cache/pypoetry/virtualenvs/eggtart-QxCesdUQ-py3.12/lib/python3.12/site-packages/starlette/routing.py", line 72, in app
    response = await func(request)
               ^^^^^^^^^^^^^^^^^^^
  File "/home/ubuntu/.cache/pypoetry/virtualenvs/eggtart-QxCesdUQ-py3.12/lib/python3.12/site-packages/fastapi/routing.py", line 278, in app
    raw_response = await run_endpoint_function(
                   ^^^^^^^^^^^^^^^^^^^^^^^^^^^^
  File "/home/ubuntu/.cache/pypoetry/virtualenvs/eggtart-QxCesdUQ-py3.12/lib/python3.12/site-packages/fastapi/routing.py", line 193, in run_endpoint_function
    return await run_in_threadpool(dependant.call, **values)
           ^^^^^^^^^^^^^^^^^^^^^^^^^^^^^^^^^^^^^^^^^^^^^^^^^
  File "/home/ubuntu/.cache/pypoetry/virtualenvs/eggtart-QxCesdUQ-py3.12/lib/python3.12/site-packages/starlette/concurrency.py", line 42, in run_in_threadpool
    return await anyio.to_thread.run_sync(func, *args)
           ^^^^^^^^^^^^^^^^^^^^^^^^^^^^^^^^^^^^^^^^^^^
  File "/home/ubuntu/.cache/pypoetry/virtualenvs/eggtart-QxCesdUQ-py3.12/lib/python3.12/site-packages/anyio/to_thread.py", line 56, in run_sync
    return await get_async_backend().run_sync_in_worker_thread(
           ^^^^^^^^^^^^^^^^^^^^^^^^^^^^^^^^^^^^^^^^^^^^^^^^^^^^
  File "/home/ubuntu/.cache/pypoetry/virtualenvs/eggtart-QxCesdUQ-py3.12/lib/python3.12/site-packages/anyio/_backends/_asyncio.py", line 2177, in run_sync_in_worker_thread
    return await future
           ^^^^^^^^^^^^
  File "/home/ubuntu/.cache/pypoetry/virtualenvs/eggtart-QxCesdUQ-py3.12/lib/python3.12/site-packages/anyio/_backends/_asyncio.py", line 859, in run
    result = context.run(func, *args)
             ^^^^^^^^^^^^^^^^^^^^^^^^
  File "/home/ubuntu/Eggtart-api-backend/src/views/login.py", line 27, in kakao_login
    return self.login_service.handle_login(access_token, "KAKAO", short)
           ^^^^^^^^^^^^^^^^^^^^^^^^^^^^^^^^^^^^^^^^^^^^^^^^^^^^^^^^^^^^^
  File "/home/ubuntu/Eggtart-api-backend/src/services/login.py", line 44, in handle_login
    user_id = self.request_kakao_user_info(access_token)
              ^^^^^^^^^^^^^^^^^^^^^^^^^^^^^^^^^^^^^^^^^^
  File "/home/ubuntu/Eggtart-api-backend/src/services/login.py", line 69, in request_kakao_user_info
    with self.transaction:
  File "/home/ubuntu/Eggtart-api-backend/src/transaction.py", line 20, in __exit__
    self.db.commit()
  File "/home/ubuntu/.cache/pypoetry/virtualenvs/eggtart-QxCesdUQ-py3.12/lib/python3.12/site-packages/sqlalchemy/orm/session.py", line 1454, in commit
    self._transaction.commit(_to_root=self.future)
  File "/home/ubuntu/.cache/pypoetry/virtualenvs/eggtart-QxCesdUQ-py3.12/lib/python3.12/site-packages/sqlalchemy/orm/session.py", line 832, in commit
    self._prepare_impl()
  File "/home/ubuntu/.cache/pypoetry/virtualenvs/eggtart-QxCesdUQ-py3.12/lib/python3.12/site-packages/sqlalchemy/orm/session.py", line 811, in _prepare_impl
    self.session.flush()
  File "/home/ubuntu/.cache/pypoetry/virtualenvs/eggtart-QxCesdUQ-py3.12/lib/python3.12/site-packages/sqlalchemy/orm/session.py", line 3449, in flush
    self._flush(objects)
  File "/home/ubuntu/.cache/pypoetry/virtualenvs/eggtart-QxCesdUQ-py3.12/lib/python3.12/site-packages/sqlalchemy/orm/session.py", line 3588, in _flush
    with util.safe_reraise():
  File "/home/ubuntu/.cache/pypoetry/virtualenvs/eggtart-QxCesdUQ-py3.12/lib/python3.12/site-packages/sqlalchemy/util/langhelpers.py", line 70, in __exit__
    compat.raise_(
  File "/home/ubuntu/.cache/pypoetry/virtualenvs/eggtart-QxCesdUQ-py3.12/lib/python3.12/site-packages/sqlalchemy/util/compat.py", line 211, in raise_
    raise exception
  File "/home/ubuntu/.cache/pypoetry/virtualenvs/eggtart-QxCesdUQ-py3.12/lib/python3.12/site-packages/sqlalchemy/orm/session.py", line 3549, in _flush
    flush_context.execute()
  File "/home/ubuntu/.cache/pypoetry/virtualenvs/eggtart-QxCesdUQ-py3.12/lib/python3.12/site-packages/sqlalchemy/orm/unitofwork.py", line 456, in execute
    rec.execute(self)
  File "/home/ubuntu/.cache/pypoetry/virtualenvs/eggtart-QxCesdUQ-py3.12/lib/python3.12/site-packages/sqlalchemy/orm/unitofwork.py", line 630, in execute
    util.preloaded.orm_persistence.save_obj(
  File "/home/ubuntu/.cache/pypoetry/virtualenvs/eggtart-QxCesdUQ-py3.12/lib/python3.12/site-packages/sqlalchemy/orm/persistence.py", line 245, in save_obj
    _emit_insert_statements(
  File "/home/ubuntu/.cache/pypoetry/virtualenvs/eggtart-QxCesdUQ-py3.12/lib/python3.12/site-packages/sqlalchemy/orm/persistence.py", line 1238, in _emit_insert_statements
    result = connection._execute_20(
             ^^^^^^^^^^^^^^^^^^^^^^^
  File "/home/ubuntu/.cache/pypoetry/virtualenvs/eggtart-QxCesdUQ-py3.12/lib/python3.12/site-packages/sqlalchemy/engine/base.py", line 1710, in _execute_20
    return meth(self, args_10style, kwargs_10style, execution_options)
           ^^^^^^^^^^^^^^^^^^^^^^^^^^^^^^^^^^^^^^^^^^^^^^^^^^^^^^^^^^^
  File "/home/ubuntu/.cache/pypoetry/virtualenvs/eggtart-QxCesdUQ-py3.12/lib/python3.12/site-packages/sqlalchemy/sql/elements.py", line 334, in _execute_on_connection
    return connection._execute_clauseelement(
           ^^^^^^^^^^^^^^^^^^^^^^^^^^^^^^^^^^
  File "/home/ubuntu/.cache/pypoetry/virtualenvs/eggtart-QxCesdUQ-py3.12/lib/python3.12/site-packages/sqlalchemy/engine/base.py", line 1577, in _execute_clauseelement
    ret = self._execute_context(
          ^^^^^^^^^^^^^^^^^^^^^^
  File "/home/ubuntu/.cache/pypoetry/virtualenvs/eggtart-QxCesdUQ-py3.12/lib/python3.12/site-packages/sqlalchemy/engine/base.py", line 1953, in _execute_context
    self._handle_dbapi_exception(
  File "/home/ubuntu/.cache/pypoetry/virtualenvs/eggtart-QxCesdUQ-py3.12/lib/python3.12/site-packages/sqlalchemy/engine/base.py", line 2134, in _handle_dbapi_exception
    util.raise_(
  File "/home/ubuntu/.cache/pypoetry/virtualenvs/eggtart-QxCesdUQ-py3.12/lib/python3.12/site-packages/sqlalchemy/util/compat.py", line 211, in raise_
    raise exception
  File "/home/ubuntu/.cache/pypoetry/virtualenvs/eggtart-QxCesdUQ-py3.12/lib/python3.12/site-packages/sqlalchemy/engine/base.py", line 1910, in _execute_context
    self.dialect.do_execute(
  File "/home/ubuntu/.cache/pypoetry/virtualenvs/eggtart-QxCesdUQ-py3.12/lib/python3.12/site-packages/sqlalchemy/engine/default.py", line 736, in do_execute
    cursor.execute(statement, parameters)
sqlalchemy.exc.DatabaseError: (cx_Oracle.DatabaseError) ORA-01950: no privileges on tablespace 'DATA'
[SQL: INSERT INTO users (nickname, social_id, social_provider, apple_refresh_token) VALUES (:nickname, :social_id, :social_provider, :apple_refresh_token) RETURNING users.id INTO :ret_0]
[parameters: {'nickname': '원진', 'social_id': 3424747083, 'social_provider': 'KAKAO', 'apple_refresh_token': None, 'ret_0': <cx_Oracle.Var of type DB_TYPE_VARCHAR with value [[], [], [], [], [], [], [], [], [], [], [], [], [], [], [], [], [], [], [], [], [], [], [], [], [], [], [], [], [], [], [], [], [], [], [], [], [], [], [], [], [], [], [], [], [], [], [], [], [], []]>}]
(Background on this error at: https://sqlalche.me/e/14/4xp6)
INFO:     162.158.90.217:0 - "GET /login/kakao?accessToken=CY1sbuCTC7Kt7GpSsCZHITeOtkXGlRN7AAAAAQoqJQ0AAAGPx_Ti0CJyl_dg0lnq&short=false HTTP/1.0" 500 Internal Server Error
ERROR:    Exception in ASGI application
Traceback (most recent call last):
  File "/home/ubuntu/.cache/pypoetry/virtualenvs/eggtart-QxCesdUQ-py3.12/lib/python3.12/site-packages/sqlalchemy/engine/base.py", line 1910, in _execute_context
    self.dialect.do_execute(
  File "/home/ubuntu/.cache/pypoetry/virtualenvs/eggtart-QxCesdUQ-py3.12/lib/python3.12/site-packages/sqlalchemy/engine/default.py", line 736, in do_execute
    cursor.execute(statement, parameters)
cx_Oracle.IntegrityError: ORA-01400: cannot insert NULL into ("EGGTART"."USERS"."ID")

The above exception was the direct cause of the following exception:

Traceback (most recent call last):
  File "/home/ubuntu/.cache/pypoetry/virtualenvs/eggtart-QxCesdUQ-py3.12/lib/python3.12/site-packages/uvicorn/protocols/http/h11_impl.py", line 407, in run_asgi
    result = await app(  # type: ignore[func-returns-value]
             ^^^^^^^^^^^^^^^^^^^^^^^^^^^^^^^^^^^^^^^^^^^^^^
  File "/home/ubuntu/.cache/pypoetry/virtualenvs/eggtart-QxCesdUQ-py3.12/lib/python3.12/site-packages/uvicorn/middleware/proxy_headers.py", line 69, in __call__
    return await self.app(scope, receive, send)
           ^^^^^^^^^^^^^^^^^^^^^^^^^^^^^^^^^^^^
  File "/home/ubuntu/.cache/pypoetry/virtualenvs/eggtart-QxCesdUQ-py3.12/lib/python3.12/site-packages/fastapi/applications.py", line 1054, in __call__
    await super().__call__(scope, receive, send)
  File "/home/ubuntu/.cache/pypoetry/virtualenvs/eggtart-QxCesdUQ-py3.12/lib/python3.12/site-packages/starlette/applications.py", line 123, in __call__
    await self.middleware_stack(scope, receive, send)
  File "/home/ubuntu/.cache/pypoetry/virtualenvs/eggtart-QxCesdUQ-py3.12/lib/python3.12/site-packages/starlette/middleware/errors.py", line 186, in __call__
    raise exc
  File "/home/ubuntu/.cache/pypoetry/virtualenvs/eggtart-QxCesdUQ-py3.12/lib/python3.12/site-packages/starlette/middleware/errors.py", line 164, in __call__
    await self.app(scope, receive, _send)
  File "/home/ubuntu/.cache/pypoetry/virtualenvs/eggtart-QxCesdUQ-py3.12/lib/python3.12/site-packages/starlette/middleware/cors.py", line 85, in __call__
    await self.app(scope, receive, send)
  File "/home/ubuntu/.cache/pypoetry/virtualenvs/eggtart-QxCesdUQ-py3.12/lib/python3.12/site-packages/starlette/middleware/exceptions.py", line 65, in __call__
    await wrap_app_handling_exceptions(self.app, conn)(scope, receive, send)
  File "/home/ubuntu/.cache/pypoetry/virtualenvs/eggtart-QxCesdUQ-py3.12/lib/python3.12/site-packages/starlette/_exception_handler.py", line 64, in wrapped_app
    raise exc
  File "/home/ubuntu/.cache/pypoetry/virtualenvs/eggtart-QxCesdUQ-py3.12/lib/python3.12/site-packages/starlette/_exception_handler.py", line 53, in wrapped_app
    await app(scope, receive, sender)
  File "/home/ubuntu/.cache/pypoetry/virtualenvs/eggtart-QxCesdUQ-py3.12/lib/python3.12/site-packages/starlette/routing.py", line 756, in __call__
    await self.middleware_stack(scope, receive, send)
  File "/home/ubuntu/.cache/pypoetry/virtualenvs/eggtart-QxCesdUQ-py3.12/lib/python3.12/site-packages/starlette/routing.py", line 776, in app
    await route.handle(scope, receive, send)
  File "/home/ubuntu/.cache/pypoetry/virtualenvs/eggtart-QxCesdUQ-py3.12/lib/python3.12/site-packages/starlette/routing.py", line 297, in handle
    await self.app(scope, receive, send)
  File "/home/ubuntu/.cache/pypoetry/virtualenvs/eggtart-QxCesdUQ-py3.12/lib/python3.12/site-packages/starlette/routing.py", line 77, in app
    await wrap_app_handling_exceptions(app, request)(scope, receive, send)
  File "/home/ubuntu/.cache/pypoetry/virtualenvs/eggtart-QxCesdUQ-py3.12/lib/python3.12/site-packages/starlette/_exception_handler.py", line 64, in wrapped_app
    raise exc
  File "/home/ubuntu/.cache/pypoetry/virtualenvs/eggtart-QxCesdUQ-py3.12/lib/python3.12/site-packages/starlette/_exception_handler.py", line 53, in wrapped_app
    await app(scope, receive, sender)
  File "/home/ubuntu/.cache/pypoetry/virtualenvs/eggtart-QxCesdUQ-py3.12/lib/python3.12/site-packages/starlette/routing.py", line 72, in app
    response = await func(request)
               ^^^^^^^^^^^^^^^^^^^
  File "/home/ubuntu/.cache/pypoetry/virtualenvs/eggtart-QxCesdUQ-py3.12/lib/python3.12/site-packages/fastapi/routing.py", line 278, in app
    raw_response = await run_endpoint_function(
                   ^^^^^^^^^^^^^^^^^^^^^^^^^^^^
  File "/home/ubuntu/.cache/pypoetry/virtualenvs/eggtart-QxCesdUQ-py3.12/lib/python3.12/site-packages/fastapi/routing.py", line 193, in run_endpoint_function
    return await run_in_threadpool(dependant.call, **values)
           ^^^^^^^^^^^^^^^^^^^^^^^^^^^^^^^^^^^^^^^^^^^^^^^^^
  File "/home/ubuntu/.cache/pypoetry/virtualenvs/eggtart-QxCesdUQ-py3.12/lib/python3.12/site-packages/starlette/concurrency.py", line 42, in run_in_threadpool
    return await anyio.to_thread.run_sync(func, *args)
           ^^^^^^^^^^^^^^^^^^^^^^^^^^^^^^^^^^^^^^^^^^^
  File "/home/ubuntu/.cache/pypoetry/virtualenvs/eggtart-QxCesdUQ-py3.12/lib/python3.12/site-packages/anyio/to_thread.py", line 56, in run_sync
    return await get_async_backend().run_sync_in_worker_thread(
           ^^^^^^^^^^^^^^^^^^^^^^^^^^^^^^^^^^^^^^^^^^^^^^^^^^^^
  File "/home/ubuntu/.cache/pypoetry/virtualenvs/eggtart-QxCesdUQ-py3.12/lib/python3.12/site-packages/anyio/_backends/_asyncio.py", line 2177, in run_sync_in_worker_thread
    return await future
           ^^^^^^^^^^^^
  File "/home/ubuntu/.cache/pypoetry/virtualenvs/eggtart-QxCesdUQ-py3.12/lib/python3.12/site-packages/anyio/_backends/_asyncio.py", line 859, in run
    result = context.run(func, *args)
             ^^^^^^^^^^^^^^^^^^^^^^^^
  File "/home/ubuntu/Eggtart-api-backend/src/views/login.py", line 27, in kakao_login
    return self.login_service.handle_login(access_token, "KAKAO", short)
           ^^^^^^^^^^^^^^^^^^^^^^^^^^^^^^^^^^^^^^^^^^^^^^^^^^^^^^^^^^^^^
  File "/home/ubuntu/Eggtart-api-backend/src/services/login.py", line 44, in handle_login
    user_id = self.request_kakao_user_info(access_token)
              ^^^^^^^^^^^^^^^^^^^^^^^^^^^^^^^^^^^^^^^^^^
  File "/home/ubuntu/Eggtart-api-backend/src/services/login.py", line 69, in request_kakao_user_info
    with self.transaction:
  File "/home/ubuntu/Eggtart-api-backend/src/transaction.py", line 20, in __exit__
    self.db.commit()
  File "/home/ubuntu/.cache/pypoetry/virtualenvs/eggtart-QxCesdUQ-py3.12/lib/python3.12/site-packages/sqlalchemy/orm/session.py", line 1454, in commit
    self._transaction.commit(_to_root=self.future)
  File "/home/ubuntu/.cache/pypoetry/virtualenvs/eggtart-QxCesdUQ-py3.12/lib/python3.12/site-packages/sqlalchemy/orm/session.py", line 832, in commit
    self._prepare_impl()
  File "/home/ubuntu/.cache/pypoetry/virtualenvs/eggtart-QxCesdUQ-py3.12/lib/python3.12/site-packages/sqlalchemy/orm/session.py", line 811, in _prepare_impl
    self.session.flush()
  File "/home/ubuntu/.cache/pypoetry/virtualenvs/eggtart-QxCesdUQ-py3.12/lib/python3.12/site-packages/sqlalchemy/orm/session.py", line 3449, in flush
    self._flush(objects)
  File "/home/ubuntu/.cache/pypoetry/virtualenvs/eggtart-QxCesdUQ-py3.12/lib/python3.12/site-packages/sqlalchemy/orm/session.py", line 3588, in _flush
    with util.safe_reraise():
  File "/home/ubuntu/.cache/pypoetry/virtualenvs/eggtart-QxCesdUQ-py3.12/lib/python3.12/site-packages/sqlalchemy/util/langhelpers.py", line 70, in __exit__
    compat.raise_(
  File "/home/ubuntu/.cache/pypoetry/virtualenvs/eggtart-QxCesdUQ-py3.12/lib/python3.12/site-packages/sqlalchemy/util/compat.py", line 211, in raise_
    raise exception
  File "/home/ubuntu/.cache/pypoetry/virtualenvs/eggtart-QxCesdUQ-py3.12/lib/python3.12/site-packages/sqlalchemy/orm/session.py", line 3549, in _flush
    flush_context.execute()
  File "/home/ubuntu/.cache/pypoetry/virtualenvs/eggtart-QxCesdUQ-py3.12/lib/python3.12/site-packages/sqlalchemy/orm/unitofwork.py", line 456, in execute
    rec.execute(self)
  File "/home/ubuntu/.cache/pypoetry/virtualenvs/eggtart-QxCesdUQ-py3.12/lib/python3.12/site-packages/sqlalchemy/orm/unitofwork.py", line 630, in execute
    util.preloaded.orm_persistence.save_obj(
  File "/home/ubuntu/.cache/pypoetry/virtualenvs/eggtart-QxCesdUQ-py3.12/lib/python3.12/site-packages/sqlalchemy/orm/persistence.py", line 245, in save_obj
    _emit_insert_statements(
  File "/home/ubuntu/.cache/pypoetry/virtualenvs/eggtart-QxCesdUQ-py3.12/lib/python3.12/site-packages/sqlalchemy/orm/persistence.py", line 1238, in _emit_insert_statements
    result = connection._execute_20(
             ^^^^^^^^^^^^^^^^^^^^^^^
  File "/home/ubuntu/.cache/pypoetry/virtualenvs/eggtart-QxCesdUQ-py3.12/lib/python3.12/site-packages/sqlalchemy/engine/base.py", line 1710, in _execute_20
    return meth(self, args_10style, kwargs_10style, execution_options)
           ^^^^^^^^^^^^^^^^^^^^^^^^^^^^^^^^^^^^^^^^^^^^^^^^^^^^^^^^^^^
  File "/home/ubuntu/.cache/pypoetry/virtualenvs/eggtart-QxCesdUQ-py3.12/lib/python3.12/site-packages/sqlalchemy/sql/elements.py", line 334, in _execute_on_connection
    return connection._execute_clauseelement(
           ^^^^^^^^^^^^^^^^^^^^^^^^^^^^^^^^^^
  File "/home/ubuntu/.cache/pypoetry/virtualenvs/eggtart-QxCesdUQ-py3.12/lib/python3.12/site-packages/sqlalchemy/engine/base.py", line 1577, in _execute_clauseelement
    ret = self._execute_context(
          ^^^^^^^^^^^^^^^^^^^^^^
  File "/home/ubuntu/.cache/pypoetry/virtualenvs/eggtart-QxCesdUQ-py3.12/lib/python3.12/site-packages/sqlalchemy/engine/base.py", line 1953, in _execute_context
    self._handle_dbapi_exception(
  File "/home/ubuntu/.cache/pypoetry/virtualenvs/eggtart-QxCesdUQ-py3.12/lib/python3.12/site-packages/sqlalchemy/engine/base.py", line 2134, in _handle_dbapi_exception
    util.raise_(
  File "/home/ubuntu/.cache/pypoetry/virtualenvs/eggtart-QxCesdUQ-py3.12/lib/python3.12/site-packages/sqlalchemy/util/compat.py", line 211, in raise_
    raise exception
  File "/home/ubuntu/.cache/pypoetry/virtualenvs/eggtart-QxCesdUQ-py3.12/lib/python3.12/site-packages/sqlalchemy/engine/base.py", line 1910, in _execute_context
    self.dialect.do_execute(
  File "/home/ubuntu/.cache/pypoetry/virtualenvs/eggtart-QxCesdUQ-py3.12/lib/python3.12/site-packages/sqlalchemy/engine/default.py", line 736, in do_execute
    cursor.execute(statement, parameters)
sqlalchemy.exc.IntegrityError: (cx_Oracle.IntegrityError) ORA-01400: cannot insert NULL into ("EGGTART"."USERS"."ID")
[SQL: INSERT INTO users (nickname, social_id, social_provider, apple_refresh_token) VALUES (:nickname, :social_id, :social_provider, :apple_refresh_token) RETURNING users.id INTO :ret_0]
[parameters: {'nickname': '원진', 'social_id': 3424747083, 'social_provider': 'KAKAO', 'apple_refresh_token': None, 'ret_0': <cx_Oracle.Var of type DB_TYPE_VARCHAR with value [[], [], [], [], [], [], [], [], [], [], [], [], [], [], [], [], [], [], [], [], [], [], [], [], [], [], [], [], [], [], [], [], [], [], [], [], [], [], [], [], [], [], [], [], [], [], [], [], [], []]>}]
(Background on this error at: https://sqlalche.me/e/14/gkpj)
INFO:     172.69.33.22:0 - "GET /login/kakao?accessToken=seV41GNnrvyHx2rY0oxmn6cDKRmAZ8MDAAAAAQoqJZAAAAGPx-_-riJyl_dg0lnq&short=false HTTP/1.0" 500 Internal Server Error
ERROR:    Exception in ASGI application
Traceback (most recent call last):
  File "/home/ubuntu/.cache/pypoetry/virtualenvs/eggtart-QxCesdUQ-py3.12/lib/python3.12/site-packages/sqlalchemy/engine/base.py", line 1910, in _execute_context
    self.dialect.do_execute(
  File "/home/ubuntu/.cache/pypoetry/virtualenvs/eggtart-QxCesdUQ-py3.12/lib/python3.12/site-packages/sqlalchemy/engine/default.py", line 736, in do_execute
    cursor.execute(statement, parameters)
cx_Oracle.IntegrityError: ORA-01400: cannot insert NULL into ("EGGTART"."USERS"."ID")

The above exception was the direct cause of the following exception:

Traceback (most recent call last):
  File "/home/ubuntu/.cache/pypoetry/virtualenvs/eggtart-QxCesdUQ-py3.12/lib/python3.12/site-packages/uvicorn/protocols/http/h11_impl.py", line 407, in run_asgi
    result = await app(  # type: ignore[func-returns-value]
             ^^^^^^^^^^^^^^^^^^^^^^^^^^^^^^^^^^^^^^^^^^^^^^
  File "/home/ubuntu/.cache/pypoetry/virtualenvs/eggtart-QxCesdUQ-py3.12/lib/python3.12/site-packages/uvicorn/middleware/proxy_headers.py", line 69, in __call__
    return await self.app(scope, receive, send)
           ^^^^^^^^^^^^^^^^^^^^^^^^^^^^^^^^^^^^
  File "/home/ubuntu/.cache/pypoetry/virtualenvs/eggtart-QxCesdUQ-py3.12/lib/python3.12/site-packages/fastapi/applications.py", line 1054, in __call__
    await super().__call__(scope, receive, send)
  File "/home/ubuntu/.cache/pypoetry/virtualenvs/eggtart-QxCesdUQ-py3.12/lib/python3.12/site-packages/starlette/applications.py", line 123, in __call__
    await self.middleware_stack(scope, receive, send)
  File "/home/ubuntu/.cache/pypoetry/virtualenvs/eggtart-QxCesdUQ-py3.12/lib/python3.12/site-packages/starlette/middleware/errors.py", line 186, in __call__
    raise exc
  File "/home/ubuntu/.cache/pypoetry/virtualenvs/eggtart-QxCesdUQ-py3.12/lib/python3.12/site-packages/starlette/middleware/errors.py", line 164, in __call__
    await self.app(scope, receive, _send)
  File "/home/ubuntu/.cache/pypoetry/virtualenvs/eggtart-QxCesdUQ-py3.12/lib/python3.12/site-packages/starlette/middleware/cors.py", line 85, in __call__
    await self.app(scope, receive, send)
  File "/home/ubuntu/.cache/pypoetry/virtualenvs/eggtart-QxCesdUQ-py3.12/lib/python3.12/site-packages/starlette/middleware/exceptions.py", line 65, in __call__
    await wrap_app_handling_exceptions(self.app, conn)(scope, receive, send)
  File "/home/ubuntu/.cache/pypoetry/virtualenvs/eggtart-QxCesdUQ-py3.12/lib/python3.12/site-packages/starlette/_exception_handler.py", line 64, in wrapped_app
    raise exc
  File "/home/ubuntu/.cache/pypoetry/virtualenvs/eggtart-QxCesdUQ-py3.12/lib/python3.12/site-packages/starlette/_exception_handler.py", line 53, in wrapped_app
    await app(scope, receive, sender)
  File "/home/ubuntu/.cache/pypoetry/virtualenvs/eggtart-QxCesdUQ-py3.12/lib/python3.12/site-packages/starlette/routing.py", line 756, in __call__
    await self.middleware_stack(scope, receive, send)
  File "/home/ubuntu/.cache/pypoetry/virtualenvs/eggtart-QxCesdUQ-py3.12/lib/python3.12/site-packages/starlette/routing.py", line 776, in app
    await route.handle(scope, receive, send)
  File "/home/ubuntu/.cache/pypoetry/virtualenvs/eggtart-QxCesdUQ-py3.12/lib/python3.12/site-packages/starlette/routing.py", line 297, in handle
    await self.app(scope, receive, send)
  File "/home/ubuntu/.cache/pypoetry/virtualenvs/eggtart-QxCesdUQ-py3.12/lib/python3.12/site-packages/starlette/routing.py", line 77, in app
    await wrap_app_handling_exceptions(app, request)(scope, receive, send)
  File "/home/ubuntu/.cache/pypoetry/virtualenvs/eggtart-QxCesdUQ-py3.12/lib/python3.12/site-packages/starlette/_exception_handler.py", line 64, in wrapped_app
    raise exc
  File "/home/ubuntu/.cache/pypoetry/virtualenvs/eggtart-QxCesdUQ-py3.12/lib/python3.12/site-packages/starlette/_exception_handler.py", line 53, in wrapped_app
    await app(scope, receive, sender)
  File "/home/ubuntu/.cache/pypoetry/virtualenvs/eggtart-QxCesdUQ-py3.12/lib/python3.12/site-packages/starlette/routing.py", line 72, in app
    response = await func(request)
               ^^^^^^^^^^^^^^^^^^^
  File "/home/ubuntu/.cache/pypoetry/virtualenvs/eggtart-QxCesdUQ-py3.12/lib/python3.12/site-packages/fastapi/routing.py", line 278, in app
    raw_response = await run_endpoint_function(
                   ^^^^^^^^^^^^^^^^^^^^^^^^^^^^
  File "/home/ubuntu/.cache/pypoetry/virtualenvs/eggtart-QxCesdUQ-py3.12/lib/python3.12/site-packages/fastapi/routing.py", line 193, in run_endpoint_function
    return await run_in_threadpool(dependant.call, **values)
           ^^^^^^^^^^^^^^^^^^^^^^^^^^^^^^^^^^^^^^^^^^^^^^^^^
  File "/home/ubuntu/.cache/pypoetry/virtualenvs/eggtart-QxCesdUQ-py3.12/lib/python3.12/site-packages/starlette/concurrency.py", line 42, in run_in_threadpool
    return await anyio.to_thread.run_sync(func, *args)
           ^^^^^^^^^^^^^^^^^^^^^^^^^^^^^^^^^^^^^^^^^^^
  File "/home/ubuntu/.cache/pypoetry/virtualenvs/eggtart-QxCesdUQ-py3.12/lib/python3.12/site-packages/anyio/to_thread.py", line 56, in run_sync
    return await get_async_backend().run_sync_in_worker_thread(
           ^^^^^^^^^^^^^^^^^^^^^^^^^^^^^^^^^^^^^^^^^^^^^^^^^^^^
  File "/home/ubuntu/.cache/pypoetry/virtualenvs/eggtart-QxCesdUQ-py3.12/lib/python3.12/site-packages/anyio/_backends/_asyncio.py", line 2177, in run_sync_in_worker_thread
    return await future
           ^^^^^^^^^^^^
  File "/home/ubuntu/.cache/pypoetry/virtualenvs/eggtart-QxCesdUQ-py3.12/lib/python3.12/site-packages/anyio/_backends/_asyncio.py", line 859, in run
    result = context.run(func, *args)
             ^^^^^^^^^^^^^^^^^^^^^^^^
  File "/home/ubuntu/Eggtart-api-backend/src/views/login.py", line 27, in kakao_login
    return self.login_service.handle_login(access_token, "KAKAO", short)
           ^^^^^^^^^^^^^^^^^^^^^^^^^^^^^^^^^^^^^^^^^^^^^^^^^^^^^^^^^^^^^
  File "/home/ubuntu/Eggtart-api-backend/src/services/login.py", line 44, in handle_login
    user_id = self.request_kakao_user_info(access_token)
              ^^^^^^^^^^^^^^^^^^^^^^^^^^^^^^^^^^^^^^^^^^
  File "/home/ubuntu/Eggtart-api-backend/src/services/login.py", line 69, in request_kakao_user_info
    with self.transaction:
  File "/home/ubuntu/Eggtart-api-backend/src/transaction.py", line 20, in __exit__
    self.db.commit()
  File "/home/ubuntu/.cache/pypoetry/virtualenvs/eggtart-QxCesdUQ-py3.12/lib/python3.12/site-packages/sqlalchemy/orm/session.py", line 1454, in commit
    self._transaction.commit(_to_root=self.future)
  File "/home/ubuntu/.cache/pypoetry/virtualenvs/eggtart-QxCesdUQ-py3.12/lib/python3.12/site-packages/sqlalchemy/orm/session.py", line 832, in commit
    self._prepare_impl()
  File "/home/ubuntu/.cache/pypoetry/virtualenvs/eggtart-QxCesdUQ-py3.12/lib/python3.12/site-packages/sqlalchemy/orm/session.py", line 811, in _prepare_impl
    self.session.flush()
  File "/home/ubuntu/.cache/pypoetry/virtualenvs/eggtart-QxCesdUQ-py3.12/lib/python3.12/site-packages/sqlalchemy/orm/session.py", line 3449, in flush
    self._flush(objects)
  File "/home/ubuntu/.cache/pypoetry/virtualenvs/eggtart-QxCesdUQ-py3.12/lib/python3.12/site-packages/sqlalchemy/orm/session.py", line 3588, in _flush
    with util.safe_reraise():
  File "/home/ubuntu/.cache/pypoetry/virtualenvs/eggtart-QxCesdUQ-py3.12/lib/python3.12/site-packages/sqlalchemy/util/langhelpers.py", line 70, in __exit__
    compat.raise_(
  File "/home/ubuntu/.cache/pypoetry/virtualenvs/eggtart-QxCesdUQ-py3.12/lib/python3.12/site-packages/sqlalchemy/util/compat.py", line 211, in raise_
    raise exception
  File "/home/ubuntu/.cache/pypoetry/virtualenvs/eggtart-QxCesdUQ-py3.12/lib/python3.12/site-packages/sqlalchemy/orm/session.py", line 3549, in _flush
    flush_context.execute()
  File "/home/ubuntu/.cache/pypoetry/virtualenvs/eggtart-QxCesdUQ-py3.12/lib/python3.12/site-packages/sqlalchemy/orm/unitofwork.py", line 456, in execute
    rec.execute(self)
  File "/home/ubuntu/.cache/pypoetry/virtualenvs/eggtart-QxCesdUQ-py3.12/lib/python3.12/site-packages/sqlalchemy/orm/unitofwork.py", line 630, in execute
    util.preloaded.orm_persistence.save_obj(
  File "/home/ubuntu/.cache/pypoetry/virtualenvs/eggtart-QxCesdUQ-py3.12/lib/python3.12/site-packages/sqlalchemy/orm/persistence.py", line 245, in save_obj
    _emit_insert_statements(
  File "/home/ubuntu/.cache/pypoetry/virtualenvs/eggtart-QxCesdUQ-py3.12/lib/python3.12/site-packages/sqlalchemy/orm/persistence.py", line 1238, in _emit_insert_statements
    result = connection._execute_20(
             ^^^^^^^^^^^^^^^^^^^^^^^
  File "/home/ubuntu/.cache/pypoetry/virtualenvs/eggtart-QxCesdUQ-py3.12/lib/python3.12/site-packages/sqlalchemy/engine/base.py", line 1710, in _execute_20
    return meth(self, args_10style, kwargs_10style, execution_options)
           ^^^^^^^^^^^^^^^^^^^^^^^^^^^^^^^^^^^^^^^^^^^^^^^^^^^^^^^^^^^
  File "/home/ubuntu/.cache/pypoetry/virtualenvs/eggtart-QxCesdUQ-py3.12/lib/python3.12/site-packages/sqlalchemy/sql/elements.py", line 334, in _execute_on_connection
    return connection._execute_clauseelement(
           ^^^^^^^^^^^^^^^^^^^^^^^^^^^^^^^^^^
  File "/home/ubuntu/.cache/pypoetry/virtualenvs/eggtart-QxCesdUQ-py3.12/lib/python3.12/site-packages/sqlalchemy/engine/base.py", line 1577, in _execute_clauseelement
    ret = self._execute_context(
          ^^^^^^^^^^^^^^^^^^^^^^
  File "/home/ubuntu/.cache/pypoetry/virtualenvs/eggtart-QxCesdUQ-py3.12/lib/python3.12/site-packages/sqlalchemy/engine/base.py", line 1953, in _execute_context
    self._handle_dbapi_exception(
  File "/home/ubuntu/.cache/pypoetry/virtualenvs/eggtart-QxCesdUQ-py3.12/lib/python3.12/site-packages/sqlalchemy/engine/base.py", line 2134, in _handle_dbapi_exception
    util.raise_(
  File "/home/ubuntu/.cache/pypoetry/virtualenvs/eggtart-QxCesdUQ-py3.12/lib/python3.12/site-packages/sqlalchemy/util/compat.py", line 211, in raise_
    raise exception
  File "/home/ubuntu/.cache/pypoetry/virtualenvs/eggtart-QxCesdUQ-py3.12/lib/python3.12/site-packages/sqlalchemy/engine/base.py", line 1910, in _execute_context
    self.dialect.do_execute(
  File "/home/ubuntu/.cache/pypoetry/virtualenvs/eggtart-QxCesdUQ-py3.12/lib/python3.12/site-packages/sqlalchemy/engine/default.py", line 736, in do_execute
    cursor.execute(statement, parameters)
sqlalchemy.exc.IntegrityError: (cx_Oracle.IntegrityError) ORA-01400: cannot insert NULL into ("EGGTART"."USERS"."ID")
[SQL: INSERT INTO users (nickname, social_id, social_provider, apple_refresh_token) VALUES (:nickname, :social_id, :social_provider, :apple_refresh_token) RETURNING users.id INTO :ret_0]
[parameters: {'nickname': '원진', 'social_id': 3424747083, 'social_provider': 'KAKAO', 'apple_refresh_token': None, 'ret_0': <cx_Oracle.Var of type DB_TYPE_VARCHAR with value [[], [], [], [], [], [], [], [], [], [], [], [], [], [], [], [], [], [], [], [], [], [], [], [], [], [], [], [], [], [], [], [], [], [], [], [], [], [], [], [], [], [], [], [], [], [], [], [], [], []]>}]
(Background on this error at: https://sqlalche.me/e/14/gkpj)
INFO:     172.69.33.22:0 - "GET /login/kakao?accessToken=seV41GNnrvyHx2rY0oxmn6cDKRmAZ8MDAAAAAQoqJZAAAAGPx-_-riJyl_dg0lnq&short=false HTTP/1.0" 500 Internal Server Error
ERROR:    Exception in ASGI application
Traceback (most recent call last):
  File "/home/ubuntu/.cache/pypoetry/virtualenvs/eggtart-QxCesdUQ-py3.12/lib/python3.12/site-packages/sqlalchemy/engine/base.py", line 1910, in _execute_context
    self.dialect.do_execute(
  File "/home/ubuntu/.cache/pypoetry/virtualenvs/eggtart-QxCesdUQ-py3.12/lib/python3.12/site-packages/sqlalchemy/engine/default.py", line 736, in do_execute
    cursor.execute(statement, parameters)
cx_Oracle.IntegrityError: ORA-01400: cannot insert NULL into ("EGGTART"."USERS"."ID")

The above exception was the direct cause of the following exception:

Traceback (most recent call last):
  File "/home/ubuntu/.cache/pypoetry/virtualenvs/eggtart-QxCesdUQ-py3.12/lib/python3.12/site-packages/uvicorn/protocols/http/h11_impl.py", line 407, in run_asgi
    result = await app(  # type: ignore[func-returns-value]
             ^^^^^^^^^^^^^^^^^^^^^^^^^^^^^^^^^^^^^^^^^^^^^^
  File "/home/ubuntu/.cache/pypoetry/virtualenvs/eggtart-QxCesdUQ-py3.12/lib/python3.12/site-packages/uvicorn/middleware/proxy_headers.py", line 69, in __call__
    return await self.app(scope, receive, send)
           ^^^^^^^^^^^^^^^^^^^^^^^^^^^^^^^^^^^^
  File "/home/ubuntu/.cache/pypoetry/virtualenvs/eggtart-QxCesdUQ-py3.12/lib/python3.12/site-packages/fastapi/applications.py", line 1054, in __call__
    await super().__call__(scope, receive, send)
  File "/home/ubuntu/.cache/pypoetry/virtualenvs/eggtart-QxCesdUQ-py3.12/lib/python3.12/site-packages/starlette/applications.py", line 123, in __call__
    await self.middleware_stack(scope, receive, send)
  File "/home/ubuntu/.cache/pypoetry/virtualenvs/eggtart-QxCesdUQ-py3.12/lib/python3.12/site-packages/starlette/middleware/errors.py", line 186, in __call__
    raise exc
  File "/home/ubuntu/.cache/pypoetry/virtualenvs/eggtart-QxCesdUQ-py3.12/lib/python3.12/site-packages/starlette/middleware/errors.py", line 164, in __call__
    await self.app(scope, receive, _send)
  File "/home/ubuntu/.cache/pypoetry/virtualenvs/eggtart-QxCesdUQ-py3.12/lib/python3.12/site-packages/starlette/middleware/cors.py", line 85, in __call__
    await self.app(scope, receive, send)
  File "/home/ubuntu/.cache/pypoetry/virtualenvs/eggtart-QxCesdUQ-py3.12/lib/python3.12/site-packages/starlette/middleware/exceptions.py", line 65, in __call__
    await wrap_app_handling_exceptions(self.app, conn)(scope, receive, send)
  File "/home/ubuntu/.cache/pypoetry/virtualenvs/eggtart-QxCesdUQ-py3.12/lib/python3.12/site-packages/starlette/_exception_handler.py", line 64, in wrapped_app
    raise exc
  File "/home/ubuntu/.cache/pypoetry/virtualenvs/eggtart-QxCesdUQ-py3.12/lib/python3.12/site-packages/starlette/_exception_handler.py", line 53, in wrapped_app
    await app(scope, receive, sender)
  File "/home/ubuntu/.cache/pypoetry/virtualenvs/eggtart-QxCesdUQ-py3.12/lib/python3.12/site-packages/starlette/routing.py", line 756, in __call__
    await self.middleware_stack(scope, receive, send)
  File "/home/ubuntu/.cache/pypoetry/virtualenvs/eggtart-QxCesdUQ-py3.12/lib/python3.12/site-packages/starlette/routing.py", line 776, in app
    await route.handle(scope, receive, send)
  File "/home/ubuntu/.cache/pypoetry/virtualenvs/eggtart-QxCesdUQ-py3.12/lib/python3.12/site-packages/starlette/routing.py", line 297, in handle
    await self.app(scope, receive, send)
  File "/home/ubuntu/.cache/pypoetry/virtualenvs/eggtart-QxCesdUQ-py3.12/lib/python3.12/site-packages/starlette/routing.py", line 77, in app
    await wrap_app_handling_exceptions(app, request)(scope, receive, send)
  File "/home/ubuntu/.cache/pypoetry/virtualenvs/eggtart-QxCesdUQ-py3.12/lib/python3.12/site-packages/starlette/_exception_handler.py", line 64, in wrapped_app
    raise exc
  File "/home/ubuntu/.cache/pypoetry/virtualenvs/eggtart-QxCesdUQ-py3.12/lib/python3.12/site-packages/starlette/_exception_handler.py", line 53, in wrapped_app
    await app(scope, receive, sender)
  File "/home/ubuntu/.cache/pypoetry/virtualenvs/eggtart-QxCesdUQ-py3.12/lib/python3.12/site-packages/starlette/routing.py", line 72, in app
    response = await func(request)
               ^^^^^^^^^^^^^^^^^^^
  File "/home/ubuntu/.cache/pypoetry/virtualenvs/eggtart-QxCesdUQ-py3.12/lib/python3.12/site-packages/fastapi/routing.py", line 278, in app
    raw_response = await run_endpoint_function(
                   ^^^^^^^^^^^^^^^^^^^^^^^^^^^^
  File "/home/ubuntu/.cache/pypoetry/virtualenvs/eggtart-QxCesdUQ-py3.12/lib/python3.12/site-packages/fastapi/routing.py", line 193, in run_endpoint_function
    return await run_in_threadpool(dependant.call, **values)
           ^^^^^^^^^^^^^^^^^^^^^^^^^^^^^^^^^^^^^^^^^^^^^^^^^
  File "/home/ubuntu/.cache/pypoetry/virtualenvs/eggtart-QxCesdUQ-py3.12/lib/python3.12/site-packages/starlette/concurrency.py", line 42, in run_in_threadpool
    return await anyio.to_thread.run_sync(func, *args)
           ^^^^^^^^^^^^^^^^^^^^^^^^^^^^^^^^^^^^^^^^^^^
  File "/home/ubuntu/.cache/pypoetry/virtualenvs/eggtart-QxCesdUQ-py3.12/lib/python3.12/site-packages/anyio/to_thread.py", line 56, in run_sync
    return await get_async_backend().run_sync_in_worker_thread(
           ^^^^^^^^^^^^^^^^^^^^^^^^^^^^^^^^^^^^^^^^^^^^^^^^^^^^
  File "/home/ubuntu/.cache/pypoetry/virtualenvs/eggtart-QxCesdUQ-py3.12/lib/python3.12/site-packages/anyio/_backends/_asyncio.py", line 2177, in run_sync_in_worker_thread
    return await future
           ^^^^^^^^^^^^
  File "/home/ubuntu/.cache/pypoetry/virtualenvs/eggtart-QxCesdUQ-py3.12/lib/python3.12/site-packages/anyio/_backends/_asyncio.py", line 859, in run
    result = context.run(func, *args)
             ^^^^^^^^^^^^^^^^^^^^^^^^
  File "/home/ubuntu/Eggtart-api-backend/src/views/login.py", line 27, in kakao_login
    return self.login_service.handle_login(access_token, "KAKAO", short)
           ^^^^^^^^^^^^^^^^^^^^^^^^^^^^^^^^^^^^^^^^^^^^^^^^^^^^^^^^^^^^^
  File "/home/ubuntu/Eggtart-api-backend/src/services/login.py", line 44, in handle_login
    user_id = self.request_kakao_user_info(access_token)
              ^^^^^^^^^^^^^^^^^^^^^^^^^^^^^^^^^^^^^^^^^^
  File "/home/ubuntu/Eggtart-api-backend/src/services/login.py", line 69, in request_kakao_user_info
    with self.transaction:
  File "/home/ubuntu/Eggtart-api-backend/src/transaction.py", line 20, in __exit__
    self.db.commit()
  File "/home/ubuntu/.cache/pypoetry/virtualenvs/eggtart-QxCesdUQ-py3.12/lib/python3.12/site-packages/sqlalchemy/orm/session.py", line 1454, in commit
    self._transaction.commit(_to_root=self.future)
  File "/home/ubuntu/.cache/pypoetry/virtualenvs/eggtart-QxCesdUQ-py3.12/lib/python3.12/site-packages/sqlalchemy/orm/session.py", line 832, in commit
    self._prepare_impl()
  File "/home/ubuntu/.cache/pypoetry/virtualenvs/eggtart-QxCesdUQ-py3.12/lib/python3.12/site-packages/sqlalchemy/orm/session.py", line 811, in _prepare_impl
    self.session.flush()
  File "/home/ubuntu/.cache/pypoetry/virtualenvs/eggtart-QxCesdUQ-py3.12/lib/python3.12/site-packages/sqlalchemy/orm/session.py", line 3449, in flush
    self._flush(objects)
  File "/home/ubuntu/.cache/pypoetry/virtualenvs/eggtart-QxCesdUQ-py3.12/lib/python3.12/site-packages/sqlalchemy/orm/session.py", line 3588, in _flush
    with util.safe_reraise():
  File "/home/ubuntu/.cache/pypoetry/virtualenvs/eggtart-QxCesdUQ-py3.12/lib/python3.12/site-packages/sqlalchemy/util/langhelpers.py", line 70, in __exit__
    compat.raise_(
  File "/home/ubuntu/.cache/pypoetry/virtualenvs/eggtart-QxCesdUQ-py3.12/lib/python3.12/site-packages/sqlalchemy/util/compat.py", line 211, in raise_
    raise exception
  File "/home/ubuntu/.cache/pypoetry/virtualenvs/eggtart-QxCesdUQ-py3.12/lib/python3.12/site-packages/sqlalchemy/orm/session.py", line 3549, in _flush
    flush_context.execute()
  File "/home/ubuntu/.cache/pypoetry/virtualenvs/eggtart-QxCesdUQ-py3.12/lib/python3.12/site-packages/sqlalchemy/orm/unitofwork.py", line 456, in execute
    rec.execute(self)
  File "/home/ubuntu/.cache/pypoetry/virtualenvs/eggtart-QxCesdUQ-py3.12/lib/python3.12/site-packages/sqlalchemy/orm/unitofwork.py", line 630, in execute
    util.preloaded.orm_persistence.save_obj(
  File "/home/ubuntu/.cache/pypoetry/virtualenvs/eggtart-QxCesdUQ-py3.12/lib/python3.12/site-packages/sqlalchemy/orm/persistence.py", line 245, in save_obj
    _emit_insert_statements(
  File "/home/ubuntu/.cache/pypoetry/virtualenvs/eggtart-QxCesdUQ-py3.12/lib/python3.12/site-packages/sqlalchemy/orm/persistence.py", line 1238, in _emit_insert_statements
    result = connection._execute_20(
             ^^^^^^^^^^^^^^^^^^^^^^^
  File "/home/ubuntu/.cache/pypoetry/virtualenvs/eggtart-QxCesdUQ-py3.12/lib/python3.12/site-packages/sqlalchemy/engine/base.py", line 1710, in _execute_20
    return meth(self, args_10style, kwargs_10style, execution_options)
           ^^^^^^^^^^^^^^^^^^^^^^^^^^^^^^^^^^^^^^^^^^^^^^^^^^^^^^^^^^^
  File "/home/ubuntu/.cache/pypoetry/virtualenvs/eggtart-QxCesdUQ-py3.12/lib/python3.12/site-packages/sqlalchemy/sql/elements.py", line 334, in _execute_on_connection
    return connection._execute_clauseelement(
           ^^^^^^^^^^^^^^^^^^^^^^^^^^^^^^^^^^
  File "/home/ubuntu/.cache/pypoetry/virtualenvs/eggtart-QxCesdUQ-py3.12/lib/python3.12/site-packages/sqlalchemy/engine/base.py", line 1577, in _execute_clauseelement
    ret = self._execute_context(
          ^^^^^^^^^^^^^^^^^^^^^^
  File "/home/ubuntu/.cache/pypoetry/virtualenvs/eggtart-QxCesdUQ-py3.12/lib/python3.12/site-packages/sqlalchemy/engine/base.py", line 1953, in _execute_context
    self._handle_dbapi_exception(
  File "/home/ubuntu/.cache/pypoetry/virtualenvs/eggtart-QxCesdUQ-py3.12/lib/python3.12/site-packages/sqlalchemy/engine/base.py", line 2134, in _handle_dbapi_exception
    util.raise_(
  File "/home/ubuntu/.cache/pypoetry/virtualenvs/eggtart-QxCesdUQ-py3.12/lib/python3.12/site-packages/sqlalchemy/util/compat.py", line 211, in raise_
    raise exception
  File "/home/ubuntu/.cache/pypoetry/virtualenvs/eggtart-QxCesdUQ-py3.12/lib/python3.12/site-packages/sqlalchemy/engine/base.py", line 1910, in _execute_context
    self.dialect.do_execute(
  File "/home/ubuntu/.cache/pypoetry/virtualenvs/eggtart-QxCesdUQ-py3.12/lib/python3.12/site-packages/sqlalchemy/engine/default.py", line 736, in do_execute
    cursor.execute(statement, parameters)
sqlalchemy.exc.IntegrityError: (cx_Oracle.IntegrityError) ORA-01400: cannot insert NULL into ("EGGTART"."USERS"."ID")
[SQL: INSERT INTO users (nickname, social_id, social_provider, apple_refresh_token) VALUES (:nickname, :social_id, :social_provider, :apple_refresh_token) RETURNING users.id INTO :ret_0]
[parameters: {'nickname': '원진', 'social_id': 3424747083, 'social_provider': 'KAKAO', 'apple_refresh_token': None, 'ret_0': <cx_Oracle.Var of type DB_TYPE_VARCHAR with value [[], [], [], [], [], [], [], [], [], [], [], [], [], [], [], [], [], [], [], [], [], [], [], [], [], [], [], [], [], [], [], [], [], [], [], [], [], [], [], [], [], [], [], [], [], [], [], [], [], []]>}]
(Background on this error at: https://sqlalche.me/e/14/gkpj)
INFO:     162.158.90.93:0 - "GET /login/kakao?accessToken=seV41GNnrvyHx2rY0oxmn6cDKRmAZ8MDAAAAAQoqJZAAAAGPx-_-riJyl_dg0lnq&short=false HTTP/1.0" 500 Internal Server Error
ERROR:    Exception in ASGI application
Traceback (most recent call last):
  File "/home/ubuntu/.cache/pypoetry/virtualenvs/eggtart-QxCesdUQ-py3.12/lib/python3.12/site-packages/sqlalchemy/engine/base.py", line 1910, in _execute_context
    self.dialect.do_execute(
  File "/home/ubuntu/.cache/pypoetry/virtualenvs/eggtart-QxCesdUQ-py3.12/lib/python3.12/site-packages/sqlalchemy/engine/default.py", line 736, in do_execute
    cursor.execute(statement, parameters)
cx_Oracle.IntegrityError: ORA-01400: cannot insert NULL into ("EGGTART"."USERS"."ID")

The above exception was the direct cause of the following exception:

Traceback (most recent call last):
  File "/home/ubuntu/.cache/pypoetry/virtualenvs/eggtart-QxCesdUQ-py3.12/lib/python3.12/site-packages/uvicorn/protocols/http/h11_impl.py", line 407, in run_asgi
    result = await app(  # type: ignore[func-returns-value]
             ^^^^^^^^^^^^^^^^^^^^^^^^^^^^^^^^^^^^^^^^^^^^^^
  File "/home/ubuntu/.cache/pypoetry/virtualenvs/eggtart-QxCesdUQ-py3.12/lib/python3.12/site-packages/uvicorn/middleware/proxy_headers.py", line 69, in __call__
    return await self.app(scope, receive, send)
           ^^^^^^^^^^^^^^^^^^^^^^^^^^^^^^^^^^^^
  File "/home/ubuntu/.cache/pypoetry/virtualenvs/eggtart-QxCesdUQ-py3.12/lib/python3.12/site-packages/fastapi/applications.py", line 1054, in __call__
    await super().__call__(scope, receive, send)
  File "/home/ubuntu/.cache/pypoetry/virtualenvs/eggtart-QxCesdUQ-py3.12/lib/python3.12/site-packages/starlette/applications.py", line 123, in __call__
    await self.middleware_stack(scope, receive, send)
  File "/home/ubuntu/.cache/pypoetry/virtualenvs/eggtart-QxCesdUQ-py3.12/lib/python3.12/site-packages/starlette/middleware/errors.py", line 186, in __call__
    raise exc
  File "/home/ubuntu/.cache/pypoetry/virtualenvs/eggtart-QxCesdUQ-py3.12/lib/python3.12/site-packages/starlette/middleware/errors.py", line 164, in __call__
    await self.app(scope, receive, _send)
  File "/home/ubuntu/.cache/pypoetry/virtualenvs/eggtart-QxCesdUQ-py3.12/lib/python3.12/site-packages/starlette/middleware/cors.py", line 85, in __call__
    await self.app(scope, receive, send)
  File "/home/ubuntu/.cache/pypoetry/virtualenvs/eggtart-QxCesdUQ-py3.12/lib/python3.12/site-packages/starlette/middleware/exceptions.py", line 65, in __call__
    await wrap_app_handling_exceptions(self.app, conn)(scope, receive, send)
  File "/home/ubuntu/.cache/pypoetry/virtualenvs/eggtart-QxCesdUQ-py3.12/lib/python3.12/site-packages/starlette/_exception_handler.py", line 64, in wrapped_app
    raise exc
  File "/home/ubuntu/.cache/pypoetry/virtualenvs/eggtart-QxCesdUQ-py3.12/lib/python3.12/site-packages/starlette/_exception_handler.py", line 53, in wrapped_app
    await app(scope, receive, sender)
  File "/home/ubuntu/.cache/pypoetry/virtualenvs/eggtart-QxCesdUQ-py3.12/lib/python3.12/site-packages/starlette/routing.py", line 756, in __call__
    await self.middleware_stack(scope, receive, send)
  File "/home/ubuntu/.cache/pypoetry/virtualenvs/eggtart-QxCesdUQ-py3.12/lib/python3.12/site-packages/starlette/routing.py", line 776, in app
    await route.handle(scope, receive, send)
  File "/home/ubuntu/.cache/pypoetry/virtualenvs/eggtart-QxCesdUQ-py3.12/lib/python3.12/site-packages/starlette/routing.py", line 297, in handle
    await self.app(scope, receive, send)
  File "/home/ubuntu/.cache/pypoetry/virtualenvs/eggtart-QxCesdUQ-py3.12/lib/python3.12/site-packages/starlette/routing.py", line 77, in app
    await wrap_app_handling_exceptions(app, request)(scope, receive, send)
  File "/home/ubuntu/.cache/pypoetry/virtualenvs/eggtart-QxCesdUQ-py3.12/lib/python3.12/site-packages/starlette/_exception_handler.py", line 64, in wrapped_app
    raise exc
  File "/home/ubuntu/.cache/pypoetry/virtualenvs/eggtart-QxCesdUQ-py3.12/lib/python3.12/site-packages/starlette/_exception_handler.py", line 53, in wrapped_app
    await app(scope, receive, sender)
  File "/home/ubuntu/.cache/pypoetry/virtualenvs/eggtart-QxCesdUQ-py3.12/lib/python3.12/site-packages/starlette/routing.py", line 72, in app
    response = await func(request)
               ^^^^^^^^^^^^^^^^^^^
  File "/home/ubuntu/.cache/pypoetry/virtualenvs/eggtart-QxCesdUQ-py3.12/lib/python3.12/site-packages/fastapi/routing.py", line 278, in app
    raw_response = await run_endpoint_function(
                   ^^^^^^^^^^^^^^^^^^^^^^^^^^^^
  File "/home/ubuntu/.cache/pypoetry/virtualenvs/eggtart-QxCesdUQ-py3.12/lib/python3.12/site-packages/fastapi/routing.py", line 193, in run_endpoint_function
    return await run_in_threadpool(dependant.call, **values)
           ^^^^^^^^^^^^^^^^^^^^^^^^^^^^^^^^^^^^^^^^^^^^^^^^^
  File "/home/ubuntu/.cache/pypoetry/virtualenvs/eggtart-QxCesdUQ-py3.12/lib/python3.12/site-packages/starlette/concurrency.py", line 42, in run_in_threadpool
    return await anyio.to_thread.run_sync(func, *args)
           ^^^^^^^^^^^^^^^^^^^^^^^^^^^^^^^^^^^^^^^^^^^
  File "/home/ubuntu/.cache/pypoetry/virtualenvs/eggtart-QxCesdUQ-py3.12/lib/python3.12/site-packages/anyio/to_thread.py", line 56, in run_sync
    return await get_async_backend().run_sync_in_worker_thread(
           ^^^^^^^^^^^^^^^^^^^^^^^^^^^^^^^^^^^^^^^^^^^^^^^^^^^^
  File "/home/ubuntu/.cache/pypoetry/virtualenvs/eggtart-QxCesdUQ-py3.12/lib/python3.12/site-packages/anyio/_backends/_asyncio.py", line 2177, in run_sync_in_worker_thread
    return await future
           ^^^^^^^^^^^^
  File "/home/ubuntu/.cache/pypoetry/virtualenvs/eggtart-QxCesdUQ-py3.12/lib/python3.12/site-packages/anyio/_backends/_asyncio.py", line 859, in run
    result = context.run(func, *args)
             ^^^^^^^^^^^^^^^^^^^^^^^^
  File "/home/ubuntu/Eggtart-api-backend/src/views/login.py", line 27, in kakao_login
    return self.login_service.handle_login(access_token, "KAKAO", short)
           ^^^^^^^^^^^^^^^^^^^^^^^^^^^^^^^^^^^^^^^^^^^^^^^^^^^^^^^^^^^^^
  File "/home/ubuntu/Eggtart-api-backend/src/services/login.py", line 44, in handle_login
    user_id = self.request_kakao_user_info(access_token)
              ^^^^^^^^^^^^^^^^^^^^^^^^^^^^^^^^^^^^^^^^^^
  File "/home/ubuntu/Eggtart-api-backend/src/services/login.py", line 69, in request_kakao_user_info
    with self.transaction:
  File "/home/ubuntu/Eggtart-api-backend/src/transaction.py", line 20, in __exit__
    self.db.commit()
  File "/home/ubuntu/.cache/pypoetry/virtualenvs/eggtart-QxCesdUQ-py3.12/lib/python3.12/site-packages/sqlalchemy/orm/session.py", line 1454, in commit
    self._transaction.commit(_to_root=self.future)
  File "/home/ubuntu/.cache/pypoetry/virtualenvs/eggtart-QxCesdUQ-py3.12/lib/python3.12/site-packages/sqlalchemy/orm/session.py", line 832, in commit
    self._prepare_impl()
  File "/home/ubuntu/.cache/pypoetry/virtualenvs/eggtart-QxCesdUQ-py3.12/lib/python3.12/site-packages/sqlalchemy/orm/session.py", line 811, in _prepare_impl
    self.session.flush()
  File "/home/ubuntu/.cache/pypoetry/virtualenvs/eggtart-QxCesdUQ-py3.12/lib/python3.12/site-packages/sqlalchemy/orm/session.py", line 3449, in flush
    self._flush(objects)
  File "/home/ubuntu/.cache/pypoetry/virtualenvs/eggtart-QxCesdUQ-py3.12/lib/python3.12/site-packages/sqlalchemy/orm/session.py", line 3588, in _flush
    with util.safe_reraise():
  File "/home/ubuntu/.cache/pypoetry/virtualenvs/eggtart-QxCesdUQ-py3.12/lib/python3.12/site-packages/sqlalchemy/util/langhelpers.py", line 70, in __exit__
    compat.raise_(
  File "/home/ubuntu/.cache/pypoetry/virtualenvs/eggtart-QxCesdUQ-py3.12/lib/python3.12/site-packages/sqlalchemy/util/compat.py", line 211, in raise_
    raise exception
  File "/home/ubuntu/.cache/pypoetry/virtualenvs/eggtart-QxCesdUQ-py3.12/lib/python3.12/site-packages/sqlalchemy/orm/session.py", line 3549, in _flush
    flush_context.execute()
  File "/home/ubuntu/.cache/pypoetry/virtualenvs/eggtart-QxCesdUQ-py3.12/lib/python3.12/site-packages/sqlalchemy/orm/unitofwork.py", line 456, in execute
    rec.execute(self)
  File "/home/ubuntu/.cache/pypoetry/virtualenvs/eggtart-QxCesdUQ-py3.12/lib/python3.12/site-packages/sqlalchemy/orm/unitofwork.py", line 630, in execute
    util.preloaded.orm_persistence.save_obj(
  File "/home/ubuntu/.cache/pypoetry/virtualenvs/eggtart-QxCesdUQ-py3.12/lib/python3.12/site-packages/sqlalchemy/orm/persistence.py", line 245, in save_obj
    _emit_insert_statements(
  File "/home/ubuntu/.cache/pypoetry/virtualenvs/eggtart-QxCesdUQ-py3.12/lib/python3.12/site-packages/sqlalchemy/orm/persistence.py", line 1238, in _emit_insert_statements
    result = connection._execute_20(
             ^^^^^^^^^^^^^^^^^^^^^^^
  File "/home/ubuntu/.cache/pypoetry/virtualenvs/eggtart-QxCesdUQ-py3.12/lib/python3.12/site-packages/sqlalchemy/engine/base.py", line 1710, in _execute_20
    return meth(self, args_10style, kwargs_10style, execution_options)
           ^^^^^^^^^^^^^^^^^^^^^^^^^^^^^^^^^^^^^^^^^^^^^^^^^^^^^^^^^^^
  File "/home/ubuntu/.cache/pypoetry/virtualenvs/eggtart-QxCesdUQ-py3.12/lib/python3.12/site-packages/sqlalchemy/sql/elements.py", line 334, in _execute_on_connection
    return connection._execute_clauseelement(
           ^^^^^^^^^^^^^^^^^^^^^^^^^^^^^^^^^^
  File "/home/ubuntu/.cache/pypoetry/virtualenvs/eggtart-QxCesdUQ-py3.12/lib/python3.12/site-packages/sqlalchemy/engine/base.py", line 1577, in _execute_clauseelement
    ret = self._execute_context(
          ^^^^^^^^^^^^^^^^^^^^^^
  File "/home/ubuntu/.cache/pypoetry/virtualenvs/eggtart-QxCesdUQ-py3.12/lib/python3.12/site-packages/sqlalchemy/engine/base.py", line 1953, in _execute_context
    self._handle_dbapi_exception(
  File "/home/ubuntu/.cache/pypoetry/virtualenvs/eggtart-QxCesdUQ-py3.12/lib/python3.12/site-packages/sqlalchemy/engine/base.py", line 2134, in _handle_dbapi_exception
    util.raise_(
  File "/home/ubuntu/.cache/pypoetry/virtualenvs/eggtart-QxCesdUQ-py3.12/lib/python3.12/site-packages/sqlalchemy/util/compat.py", line 211, in raise_
    raise exception
  File "/home/ubuntu/.cache/pypoetry/virtualenvs/eggtart-QxCesdUQ-py3.12/lib/python3.12/site-packages/sqlalchemy/engine/base.py", line 1910, in _execute_context
    self.dialect.do_execute(
  File "/home/ubuntu/.cache/pypoetry/virtualenvs/eggtart-QxCesdUQ-py3.12/lib/python3.12/site-packages/sqlalchemy/engine/default.py", line 736, in do_execute
    cursor.execute(statement, parameters)
sqlalchemy.exc.IntegrityError: (cx_Oracle.IntegrityError) ORA-01400: cannot insert NULL into ("EGGTART"."USERS"."ID")
[SQL: INSERT INTO users (nickname, social_id, social_provider, apple_refresh_token) VALUES (:nickname, :social_id, :social_provider, :apple_refresh_token) RETURNING users.id INTO :ret_0]
[parameters: {'nickname': '원진', 'social_id': 3424747083, 'social_provider': 'KAKAO', 'apple_refresh_token': None, 'ret_0': <cx_Oracle.Var of type DB_TYPE_VARCHAR with value [[], [], [], [], [], [], [], [], [], [], [], [], [], [], [], [], [], [], [], [], [], [], [], [], [], [], [], [], [], [], [], [], [], [], [], [], [], [], [], [], [], [], [], [], [], [], [], [], [], []]>}]
(Background on this error at: https://sqlalche.me/e/14/gkpj)
INFO:     172.70.211.215:0 - "GET /token HTTP/1.0" 200 OK
INFO:     162.158.186.127:0 - "GET /sheet HTTP/1.0" 200 OK
INFO:     162.158.186.127:0 - "POST /sheet HTTP/1.0" 500 Internal Server Error
ERROR:    Exception in ASGI application
Traceback (most recent call last):
  File "/home/ubuntu/.cache/pypoetry/virtualenvs/eggtart-QxCesdUQ-py3.12/lib/python3.12/site-packages/sqlalchemy/engine/base.py", line 1910, in _execute_context
    self.dialect.do_execute(
  File "/home/ubuntu/.cache/pypoetry/virtualenvs/eggtart-QxCesdUQ-py3.12/lib/python3.12/site-packages/sqlalchemy/engine/default.py", line 736, in do_execute
    cursor.execute(statement, parameters)
cx_Oracle.IntegrityError: ORA-01400: cannot insert NULL into ("EGGTART"."SHEETS"."ID")

The above exception was the direct cause of the following exception:

Traceback (most recent call last):
  File "/home/ubuntu/.cache/pypoetry/virtualenvs/eggtart-QxCesdUQ-py3.12/lib/python3.12/site-packages/uvicorn/protocols/http/h11_impl.py", line 407, in run_asgi
    result = await app(  # type: ignore[func-returns-value]
             ^^^^^^^^^^^^^^^^^^^^^^^^^^^^^^^^^^^^^^^^^^^^^^
  File "/home/ubuntu/.cache/pypoetry/virtualenvs/eggtart-QxCesdUQ-py3.12/lib/python3.12/site-packages/uvicorn/middleware/proxy_headers.py", line 69, in __call__
    return await self.app(scope, receive, send)
           ^^^^^^^^^^^^^^^^^^^^^^^^^^^^^^^^^^^^
  File "/home/ubuntu/.cache/pypoetry/virtualenvs/eggtart-QxCesdUQ-py3.12/lib/python3.12/site-packages/fastapi/applications.py", line 1054, in __call__
    await super().__call__(scope, receive, send)
  File "/home/ubuntu/.cache/pypoetry/virtualenvs/eggtart-QxCesdUQ-py3.12/lib/python3.12/site-packages/starlette/applications.py", line 123, in __call__
    await self.middleware_stack(scope, receive, send)
  File "/home/ubuntu/.cache/pypoetry/virtualenvs/eggtart-QxCesdUQ-py3.12/lib/python3.12/site-packages/starlette/middleware/errors.py", line 186, in __call__
    raise exc
  File "/home/ubuntu/.cache/pypoetry/virtualenvs/eggtart-QxCesdUQ-py3.12/lib/python3.12/site-packages/starlette/middleware/errors.py", line 164, in __call__
    await self.app(scope, receive, _send)
  File "/home/ubuntu/.cache/pypoetry/virtualenvs/eggtart-QxCesdUQ-py3.12/lib/python3.12/site-packages/starlette/middleware/cors.py", line 85, in __call__
    await self.app(scope, receive, send)
  File "/home/ubuntu/.cache/pypoetry/virtualenvs/eggtart-QxCesdUQ-py3.12/lib/python3.12/site-packages/starlette/middleware/exceptions.py", line 65, in __call__
    await wrap_app_handling_exceptions(self.app, conn)(scope, receive, send)
  File "/home/ubuntu/.cache/pypoetry/virtualenvs/eggtart-QxCesdUQ-py3.12/lib/python3.12/site-packages/starlette/_exception_handler.py", line 64, in wrapped_app
    raise exc
  File "/home/ubuntu/.cache/pypoetry/virtualenvs/eggtart-QxCesdUQ-py3.12/lib/python3.12/site-packages/starlette/_exception_handler.py", line 53, in wrapped_app
    await app(scope, receive, sender)
  File "/home/ubuntu/.cache/pypoetry/virtualenvs/eggtart-QxCesdUQ-py3.12/lib/python3.12/site-packages/starlette/routing.py", line 756, in __call__
    await self.middleware_stack(scope, receive, send)
  File "/home/ubuntu/.cache/pypoetry/virtualenvs/eggtart-QxCesdUQ-py3.12/lib/python3.12/site-packages/starlette/routing.py", line 776, in app
    await route.handle(scope, receive, send)
  File "/home/ubuntu/.cache/pypoetry/virtualenvs/eggtart-QxCesdUQ-py3.12/lib/python3.12/site-packages/starlette/routing.py", line 297, in handle
    await self.app(scope, receive, send)
  File "/home/ubuntu/.cache/pypoetry/virtualenvs/eggtart-QxCesdUQ-py3.12/lib/python3.12/site-packages/starlette/routing.py", line 77, in app
    await wrap_app_handling_exceptions(app, request)(scope, receive, send)
  File "/home/ubuntu/.cache/pypoetry/virtualenvs/eggtart-QxCesdUQ-py3.12/lib/python3.12/site-packages/starlette/_exception_handler.py", line 64, in wrapped_app
    raise exc
  File "/home/ubuntu/.cache/pypoetry/virtualenvs/eggtart-QxCesdUQ-py3.12/lib/python3.12/site-packages/starlette/_exception_handler.py", line 53, in wrapped_app
    await app(scope, receive, sender)
  File "/home/ubuntu/.cache/pypoetry/virtualenvs/eggtart-QxCesdUQ-py3.12/lib/python3.12/site-packages/starlette/routing.py", line 72, in app
    response = await func(request)
               ^^^^^^^^^^^^^^^^^^^
  File "/home/ubuntu/.cache/pypoetry/virtualenvs/eggtart-QxCesdUQ-py3.12/lib/python3.12/site-packages/fastapi/routing.py", line 278, in app
    raw_response = await run_endpoint_function(
                   ^^^^^^^^^^^^^^^^^^^^^^^^^^^^
  File "/home/ubuntu/.cache/pypoetry/virtualenvs/eggtart-QxCesdUQ-py3.12/lib/python3.12/site-packages/fastapi/routing.py", line 193, in run_endpoint_function
    return await run_in_threadpool(dependant.call, **values)
           ^^^^^^^^^^^^^^^^^^^^^^^^^^^^^^^^^^^^^^^^^^^^^^^^^
  File "/home/ubuntu/.cache/pypoetry/virtualenvs/eggtart-QxCesdUQ-py3.12/lib/python3.12/site-packages/starlette/concurrency.py", line 42, in run_in_threadpool
    return await anyio.to_thread.run_sync(func, *args)
           ^^^^^^^^^^^^^^^^^^^^^^^^^^^^^^^^^^^^^^^^^^^
  File "/home/ubuntu/.cache/pypoetry/virtualenvs/eggtart-QxCesdUQ-py3.12/lib/python3.12/site-packages/anyio/to_thread.py", line 56, in run_sync
    return await get_async_backend().run_sync_in_worker_thread(
           ^^^^^^^^^^^^^^^^^^^^^^^^^^^^^^^^^^^^^^^^^^^^^^^^^^^^
  File "/home/ubuntu/.cache/pypoetry/virtualenvs/eggtart-QxCesdUQ-py3.12/lib/python3.12/site-packages/anyio/_backends/_asyncio.py", line 2177, in run_sync_in_worker_thread
    return await future
           ^^^^^^^^^^^^
  File "/home/ubuntu/.cache/pypoetry/virtualenvs/eggtart-QxCesdUQ-py3.12/lib/python3.12/site-packages/anyio/_backends/_asyncio.py", line 859, in run
    result = context.run(func, *args)
             ^^^^^^^^^^^^^^^^^^^^^^^^
  File "/home/ubuntu/Eggtart-api-backend/src/views/sheet.py", line 21, in create_sheet
    created_sheet = self.sheet_service.create_sheet(dto, user_id)
                    ^^^^^^^^^^^^^^^^^^^^^^^^^^^^^^^^^^^^^^^^^^^^^
  File "/home/ubuntu/Eggtart-api-backend/src/services/sheet.py", line 38, in create_sheet
    with self.transaction:
  File "/home/ubuntu/Eggtart-api-backend/src/transaction.py", line 20, in __exit__
    self.db.commit()
  File "/home/ubuntu/.cache/pypoetry/virtualenvs/eggtart-QxCesdUQ-py3.12/lib/python3.12/site-packages/sqlalchemy/orm/session.py", line 1454, in commit
    self._transaction.commit(_to_root=self.future)
  File "/home/ubuntu/.cache/pypoetry/virtualenvs/eggtart-QxCesdUQ-py3.12/lib/python3.12/site-packages/sqlalchemy/orm/session.py", line 832, in commit
    self._prepare_impl()
  File "/home/ubuntu/.cache/pypoetry/virtualenvs/eggtart-QxCesdUQ-py3.12/lib/python3.12/site-packages/sqlalchemy/orm/session.py", line 811, in _prepare_impl
    self.session.flush()
  File "/home/ubuntu/.cache/pypoetry/virtualenvs/eggtart-QxCesdUQ-py3.12/lib/python3.12/site-packages/sqlalchemy/orm/session.py", line 3449, in flush
    self._flush(objects)
  File "/home/ubuntu/.cache/pypoetry/virtualenvs/eggtart-QxCesdUQ-py3.12/lib/python3.12/site-packages/sqlalchemy/orm/session.py", line 3588, in _flush
    with util.safe_reraise():
  File "/home/ubuntu/.cache/pypoetry/virtualenvs/eggtart-QxCesdUQ-py3.12/lib/python3.12/site-packages/sqlalchemy/util/langhelpers.py", line 70, in __exit__
    compat.raise_(
  File "/home/ubuntu/.cache/pypoetry/virtualenvs/eggtart-QxCesdUQ-py3.12/lib/python3.12/site-packages/sqlalchemy/util/compat.py", line 211, in raise_
    raise exception
  File "/home/ubuntu/.cache/pypoetry/virtualenvs/eggtart-QxCesdUQ-py3.12/lib/python3.12/site-packages/sqlalchemy/orm/session.py", line 3549, in _flush
    flush_context.execute()
  File "/home/ubuntu/.cache/pypoetry/virtualenvs/eggtart-QxCesdUQ-py3.12/lib/python3.12/site-packages/sqlalchemy/orm/unitofwork.py", line 453, in execute
    n.execute_aggregate(self, set_)
  File "/home/ubuntu/.cache/pypoetry/virtualenvs/eggtart-QxCesdUQ-py3.12/lib/python3.12/site-packages/sqlalchemy/orm/unitofwork.py", line 555, in execute_aggregate
    self.execute(uow)
  File "/home/ubuntu/.cache/pypoetry/virtualenvs/eggtart-QxCesdUQ-py3.12/lib/python3.12/site-packages/sqlalchemy/orm/unitofwork.py", line 630, in execute
    util.preloaded.orm_persistence.save_obj(
  File "/home/ubuntu/.cache/pypoetry/virtualenvs/eggtart-QxCesdUQ-py3.12/lib/python3.12/site-packages/sqlalchemy/orm/persistence.py", line 245, in save_obj
    _emit_insert_statements(
  File "/home/ubuntu/.cache/pypoetry/virtualenvs/eggtart-QxCesdUQ-py3.12/lib/python3.12/site-packages/sqlalchemy/orm/persistence.py", line 1238, in _emit_insert_statements
    result = connection._execute_20(
             ^^^^^^^^^^^^^^^^^^^^^^^
  File "/home/ubuntu/.cache/pypoetry/virtualenvs/eggtart-QxCesdUQ-py3.12/lib/python3.12/site-packages/sqlalchemy/engine/base.py", line 1710, in _execute_20
    return meth(self, args_10style, kwargs_10style, execution_options)
           ^^^^^^^^^^^^^^^^^^^^^^^^^^^^^^^^^^^^^^^^^^^^^^^^^^^^^^^^^^^
  File "/home/ubuntu/.cache/pypoetry/virtualenvs/eggtart-QxCesdUQ-py3.12/lib/python3.12/site-packages/sqlalchemy/sql/elements.py", line 334, in _execute_on_connection
    return connection._execute_clauseelement(
           ^^^^^^^^^^^^^^^^^^^^^^^^^^^^^^^^^^
  File "/home/ubuntu/.cache/pypoetry/virtualenvs/eggtart-QxCesdUQ-py3.12/lib/python3.12/site-packages/sqlalchemy/engine/base.py", line 1577, in _execute_clauseelement
    ret = self._execute_context(
          ^^^^^^^^^^^^^^^^^^^^^^
  File "/home/ubuntu/.cache/pypoetry/virtualenvs/eggtart-QxCesdUQ-py3.12/lib/python3.12/site-packages/sqlalchemy/engine/base.py", line 1953, in _execute_context
    self._handle_dbapi_exception(
  File "/home/ubuntu/.cache/pypoetry/virtualenvs/eggtart-QxCesdUQ-py3.12/lib/python3.12/site-packages/sqlalchemy/engine/base.py", line 2134, in _handle_dbapi_exception
    util.raise_(
  File "/home/ubuntu/.cache/pypoetry/virtualenvs/eggtart-QxCesdUQ-py3.12/lib/python3.12/site-packages/sqlalchemy/util/compat.py", line 211, in raise_
    raise exception
  File "/home/ubuntu/.cache/pypoetry/virtualenvs/eggtart-QxCesdUQ-py3.12/lib/python3.12/site-packages/sqlalchemy/engine/base.py", line 1910, in _execute_context
    self.dialect.do_execute(
  File "/home/ubuntu/.cache/pypoetry/virtualenvs/eggtart-QxCesdUQ-py3.12/lib/python3.12/site-packages/sqlalchemy/engine/default.py", line 736, in do_execute
    cursor.execute(statement, parameters)
sqlalchemy.exc.IntegrityError: (cx_Oracle.IntegrityError) ORA-01400: cannot insert NULL into ("EGGTART"."SHEETS"."ID")
[SQL: INSERT INTO sheets (owner_id, name, created_at, modified_at) VALUES (:owner_id, :name, :created_at, :modified_at) RETURNING sheets.id INTO :ret_0]
[parameters: {'owner_id': 7, 'name': '', 'created_at': datetime.datetime(2024, 5, 30, 5, 30, 44, 772857), 'modified_at': None, 'ret_0': <cx_Oracle.Var of type DB_TYPE_VARCHAR with value [[], [], [], [], [], [], [], [], [], [], [], [], [], [], [], [], [], [], [], [], [], [], [], [], [], [], [], [], [], [], [], [], [], [], [], [], [], [], [], [], [], [], [], [], [], [], [], [], [], []]>}]
(Background on this error at: https://sqlalche.me/e/14/gkpj)
INFO:     Started server process [1364188]
INFO:     Waiting for application startup.
INFO:     Application startup complete.
INFO:     Uvicorn running on http://0.0.0.0:8000 (Press CTRL+C to quit)
INFO:     Started server process [1364589]
INFO:     Waiting for application startup.
INFO:     Application startup complete.
INFO:     Uvicorn running on http://0.0.0.0:8000 (Press CTRL+C to quit)
INFO:     172.70.214.109:0 - "GET /login/kakao?accessToken=ISw4S3fM-Qtrtf1zcmcfyphY5ehajoudAAAAAQo9cxcAAAGPyAG_WiJyl_dg0lnq&short=false HTTP/1.0" 500 Internal Server Error
ERROR:    Exception in ASGI application
Traceback (most recent call last):
  File "/home/ubuntu/.cache/pypoetry/virtualenvs/eggtart-QxCesdUQ-py3.12/lib/python3.12/site-packages/sqlalchemy/engine/base.py", line 1910, in _execute_context
    self.dialect.do_execute(
  File "/home/ubuntu/.cache/pypoetry/virtualenvs/eggtart-QxCesdUQ-py3.12/lib/python3.12/site-packages/sqlalchemy/engine/default.py", line 736, in do_execute
    cursor.execute(statement, parameters)
cx_Oracle.DatabaseError: ORA-02289: sequence does not exist

The above exception was the direct cause of the following exception:

Traceback (most recent call last):
  File "/home/ubuntu/.cache/pypoetry/virtualenvs/eggtart-QxCesdUQ-py3.12/lib/python3.12/site-packages/uvicorn/protocols/http/h11_impl.py", line 407, in run_asgi
    result = await app(  # type: ignore[func-returns-value]
             ^^^^^^^^^^^^^^^^^^^^^^^^^^^^^^^^^^^^^^^^^^^^^^
  File "/home/ubuntu/.cache/pypoetry/virtualenvs/eggtart-QxCesdUQ-py3.12/lib/python3.12/site-packages/uvicorn/middleware/proxy_headers.py", line 69, in __call__
    return await self.app(scope, receive, send)
           ^^^^^^^^^^^^^^^^^^^^^^^^^^^^^^^^^^^^
  File "/home/ubuntu/.cache/pypoetry/virtualenvs/eggtart-QxCesdUQ-py3.12/lib/python3.12/site-packages/fastapi/applications.py", line 1054, in __call__
    await super().__call__(scope, receive, send)
  File "/home/ubuntu/.cache/pypoetry/virtualenvs/eggtart-QxCesdUQ-py3.12/lib/python3.12/site-packages/starlette/applications.py", line 123, in __call__
    await self.middleware_stack(scope, receive, send)
  File "/home/ubuntu/.cache/pypoetry/virtualenvs/eggtart-QxCesdUQ-py3.12/lib/python3.12/site-packages/starlette/middleware/errors.py", line 186, in __call__
    raise exc
  File "/home/ubuntu/.cache/pypoetry/virtualenvs/eggtart-QxCesdUQ-py3.12/lib/python3.12/site-packages/starlette/middleware/errors.py", line 164, in __call__
    await self.app(scope, receive, _send)
  File "/home/ubuntu/.cache/pypoetry/virtualenvs/eggtart-QxCesdUQ-py3.12/lib/python3.12/site-packages/starlette/middleware/cors.py", line 85, in __call__
    await self.app(scope, receive, send)
  File "/home/ubuntu/.cache/pypoetry/virtualenvs/eggtart-QxCesdUQ-py3.12/lib/python3.12/site-packages/starlette/middleware/exceptions.py", line 65, in __call__
    await wrap_app_handling_exceptions(self.app, conn)(scope, receive, send)
  File "/home/ubuntu/.cache/pypoetry/virtualenvs/eggtart-QxCesdUQ-py3.12/lib/python3.12/site-packages/starlette/_exception_handler.py", line 64, in wrapped_app
    raise exc
  File "/home/ubuntu/.cache/pypoetry/virtualenvs/eggtart-QxCesdUQ-py3.12/lib/python3.12/site-packages/starlette/_exception_handler.py", line 53, in wrapped_app
    await app(scope, receive, sender)
  File "/home/ubuntu/.cache/pypoetry/virtualenvs/eggtart-QxCesdUQ-py3.12/lib/python3.12/site-packages/starlette/routing.py", line 756, in __call__
    await self.middleware_stack(scope, receive, send)
  File "/home/ubuntu/.cache/pypoetry/virtualenvs/eggtart-QxCesdUQ-py3.12/lib/python3.12/site-packages/starlette/routing.py", line 776, in app
    await route.handle(scope, receive, send)
  File "/home/ubuntu/.cache/pypoetry/virtualenvs/eggtart-QxCesdUQ-py3.12/lib/python3.12/site-packages/starlette/routing.py", line 297, in handle
    await self.app(scope, receive, send)
  File "/home/ubuntu/.cache/pypoetry/virtualenvs/eggtart-QxCesdUQ-py3.12/lib/python3.12/site-packages/starlette/routing.py", line 77, in app
    await wrap_app_handling_exceptions(app, request)(scope, receive, send)
  File "/home/ubuntu/.cache/pypoetry/virtualenvs/eggtart-QxCesdUQ-py3.12/lib/python3.12/site-packages/starlette/_exception_handler.py", line 64, in wrapped_app
    raise exc
  File "/home/ubuntu/.cache/pypoetry/virtualenvs/eggtart-QxCesdUQ-py3.12/lib/python3.12/site-packages/starlette/_exception_handler.py", line 53, in wrapped_app
    await app(scope, receive, sender)
  File "/home/ubuntu/.cache/pypoetry/virtualenvs/eggtart-QxCesdUQ-py3.12/lib/python3.12/site-packages/starlette/routing.py", line 72, in app
    response = await func(request)
               ^^^^^^^^^^^^^^^^^^^
  File "/home/ubuntu/.cache/pypoetry/virtualenvs/eggtart-QxCesdUQ-py3.12/lib/python3.12/site-packages/fastapi/routing.py", line 278, in app
    raw_response = await run_endpoint_function(
                   ^^^^^^^^^^^^^^^^^^^^^^^^^^^^
  File "/home/ubuntu/.cache/pypoetry/virtualenvs/eggtart-QxCesdUQ-py3.12/lib/python3.12/site-packages/fastapi/routing.py", line 193, in run_endpoint_function
    return await run_in_threadpool(dependant.call, **values)
           ^^^^^^^^^^^^^^^^^^^^^^^^^^^^^^^^^^^^^^^^^^^^^^^^^
  File "/home/ubuntu/.cache/pypoetry/virtualenvs/eggtart-QxCesdUQ-py3.12/lib/python3.12/site-packages/starlette/concurrency.py", line 42, in run_in_threadpool
    return await anyio.to_thread.run_sync(func, *args)
           ^^^^^^^^^^^^^^^^^^^^^^^^^^^^^^^^^^^^^^^^^^^
  File "/home/ubuntu/.cache/pypoetry/virtualenvs/eggtart-QxCesdUQ-py3.12/lib/python3.12/site-packages/anyio/to_thread.py", line 56, in run_sync
    return await get_async_backend().run_sync_in_worker_thread(
           ^^^^^^^^^^^^^^^^^^^^^^^^^^^^^^^^^^^^^^^^^^^^^^^^^^^^
  File "/home/ubuntu/.cache/pypoetry/virtualenvs/eggtart-QxCesdUQ-py3.12/lib/python3.12/site-packages/anyio/_backends/_asyncio.py", line 2177, in run_sync_in_worker_thread
    return await future
           ^^^^^^^^^^^^
  File "/home/ubuntu/.cache/pypoetry/virtualenvs/eggtart-QxCesdUQ-py3.12/lib/python3.12/site-packages/anyio/_backends/_asyncio.py", line 859, in run
    result = context.run(func, *args)
             ^^^^^^^^^^^^^^^^^^^^^^^^
  File "/home/ubuntu/Eggtart-api-backend/src/views/login.py", line 27, in kakao_login
    return self.login_service.handle_login(access_token, "KAKAO", short)
           ^^^^^^^^^^^^^^^^^^^^^^^^^^^^^^^^^^^^^^^^^^^^^^^^^^^^^^^^^^^^^
  File "/home/ubuntu/Eggtart-api-backend/src/services/login.py", line 44, in handle_login
    user_id = self.request_kakao_user_info(access_token)
              ^^^^^^^^^^^^^^^^^^^^^^^^^^^^^^^^^^^^^^^^^^
  File "/home/ubuntu/Eggtart-api-backend/src/services/login.py", line 69, in request_kakao_user_info
    with self.transaction:
  File "/home/ubuntu/Eggtart-api-backend/src/transaction.py", line 20, in __exit__
    self.db.commit()
  File "/home/ubuntu/.cache/pypoetry/virtualenvs/eggtart-QxCesdUQ-py3.12/lib/python3.12/site-packages/sqlalchemy/orm/session.py", line 1454, in commit
    self._transaction.commit(_to_root=self.future)
  File "/home/ubuntu/.cache/pypoetry/virtualenvs/eggtart-QxCesdUQ-py3.12/lib/python3.12/site-packages/sqlalchemy/orm/session.py", line 832, in commit
    self._prepare_impl()
  File "/home/ubuntu/.cache/pypoetry/virtualenvs/eggtart-QxCesdUQ-py3.12/lib/python3.12/site-packages/sqlalchemy/orm/session.py", line 811, in _prepare_impl
    self.session.flush()
  File "/home/ubuntu/.cache/pypoetry/virtualenvs/eggtart-QxCesdUQ-py3.12/lib/python3.12/site-packages/sqlalchemy/orm/session.py", line 3449, in flush
    self._flush(objects)
  File "/home/ubuntu/.cache/pypoetry/virtualenvs/eggtart-QxCesdUQ-py3.12/lib/python3.12/site-packages/sqlalchemy/orm/session.py", line 3588, in _flush
    with util.safe_reraise():
  File "/home/ubuntu/.cache/pypoetry/virtualenvs/eggtart-QxCesdUQ-py3.12/lib/python3.12/site-packages/sqlalchemy/util/langhelpers.py", line 70, in __exit__
    compat.raise_(
  File "/home/ubuntu/.cache/pypoetry/virtualenvs/eggtart-QxCesdUQ-py3.12/lib/python3.12/site-packages/sqlalchemy/util/compat.py", line 211, in raise_
    raise exception
  File "/home/ubuntu/.cache/pypoetry/virtualenvs/eggtart-QxCesdUQ-py3.12/lib/python3.12/site-packages/sqlalchemy/orm/session.py", line 3549, in _flush
    flush_context.execute()
  File "/home/ubuntu/.cache/pypoetry/virtualenvs/eggtart-QxCesdUQ-py3.12/lib/python3.12/site-packages/sqlalchemy/orm/unitofwork.py", line 456, in execute
    rec.execute(self)
  File "/home/ubuntu/.cache/pypoetry/virtualenvs/eggtart-QxCesdUQ-py3.12/lib/python3.12/site-packages/sqlalchemy/orm/unitofwork.py", line 630, in execute
    util.preloaded.orm_persistence.save_obj(
  File "/home/ubuntu/.cache/pypoetry/virtualenvs/eggtart-QxCesdUQ-py3.12/lib/python3.12/site-packages/sqlalchemy/orm/persistence.py", line 245, in save_obj
    _emit_insert_statements(
  File "/home/ubuntu/.cache/pypoetry/virtualenvs/eggtart-QxCesdUQ-py3.12/lib/python3.12/site-packages/sqlalchemy/orm/persistence.py", line 1238, in _emit_insert_statements
    result = connection._execute_20(
             ^^^^^^^^^^^^^^^^^^^^^^^
  File "/home/ubuntu/.cache/pypoetry/virtualenvs/eggtart-QxCesdUQ-py3.12/lib/python3.12/site-packages/sqlalchemy/engine/base.py", line 1710, in _execute_20
    return meth(self, args_10style, kwargs_10style, execution_options)
           ^^^^^^^^^^^^^^^^^^^^^^^^^^^^^^^^^^^^^^^^^^^^^^^^^^^^^^^^^^^
  File "/home/ubuntu/.cache/pypoetry/virtualenvs/eggtart-QxCesdUQ-py3.12/lib/python3.12/site-packages/sqlalchemy/sql/elements.py", line 334, in _execute_on_connection
    return connection._execute_clauseelement(
           ^^^^^^^^^^^^^^^^^^^^^^^^^^^^^^^^^^
  File "/home/ubuntu/.cache/pypoetry/virtualenvs/eggtart-QxCesdUQ-py3.12/lib/python3.12/site-packages/sqlalchemy/engine/base.py", line 1577, in _execute_clauseelement
    ret = self._execute_context(
          ^^^^^^^^^^^^^^^^^^^^^^
  File "/home/ubuntu/.cache/pypoetry/virtualenvs/eggtart-QxCesdUQ-py3.12/lib/python3.12/site-packages/sqlalchemy/engine/base.py", line 1953, in _execute_context
    self._handle_dbapi_exception(
  File "/home/ubuntu/.cache/pypoetry/virtualenvs/eggtart-QxCesdUQ-py3.12/lib/python3.12/site-packages/sqlalchemy/engine/base.py", line 2134, in _handle_dbapi_exception
    util.raise_(
  File "/home/ubuntu/.cache/pypoetry/virtualenvs/eggtart-QxCesdUQ-py3.12/lib/python3.12/site-packages/sqlalchemy/util/compat.py", line 211, in raise_
    raise exception
  File "/home/ubuntu/.cache/pypoetry/virtualenvs/eggtart-QxCesdUQ-py3.12/lib/python3.12/site-packages/sqlalchemy/engine/base.py", line 1910, in _execute_context
    self.dialect.do_execute(
  File "/home/ubuntu/.cache/pypoetry/virtualenvs/eggtart-QxCesdUQ-py3.12/lib/python3.12/site-packages/sqlalchemy/engine/default.py", line 736, in do_execute
    cursor.execute(statement, parameters)
sqlalchemy.exc.DatabaseError: (cx_Oracle.DatabaseError) ORA-02289: sequence does not exist
[SQL: INSERT INTO users (id, nickname, social_id, social_provider, apple_refresh_token) VALUES (user_id_seq.nextval, :nickname, :social_id, :social_provider, :apple_refresh_token) RETURNING users.id INTO :ret_0]
[parameters: {'nickname': '원진', 'social_id': 3424747083, 'social_provider': 'KAKAO', 'apple_refresh_token': None, 'ret_0': <cx_Oracle.Var of type DB_TYPE_VARCHAR with value [[], [], [], [], [], [], [], [], [], [], [], [], [], [], [], [], [], [], [], [], [], [], [], [], [], [], [], [], [], [], [], [], [], [], [], [], [], [], [], [], [], [], [], [], [], [], [], [], [], []]>}]
(Background on this error at: https://sqlalche.me/e/14/4xp6)
